Workbook

Sheet インプット表
A1: 所得金額（損益通算前） | C1: 前期 | D1: 当期 | J1: 前期 | K1: 当期
A2: 事業所得（営業等） | C2: 12202436 | D2: 5000000 | H2: 社会保険料控除 | J2: 703890 | K2: 630000 | Q2: 金額を入力
A3: 事業所得（農業） | H3: 小規模企業共済等掛金控除 | Q3: 選択
A4: 不動産所得 | H4: 生命保険料控除 | Q4: 人数または寄付先団体数を入力
A5: 配当所得 | H5: 地震保険料控除
A6: 給与所得 | C6: 550000 | H6: 寡婦控除 | J6: × | K6: ×
A7: 雑所得（公的年金等） | C7: 1078634 | H7: ひとり親控除 | J7: × | K7: ×
A8: 雑所得（業務） | H8: 勤労学生控除 | J8: × | K8: ×
A9: 雑所得（その他） | H9: 障碍者控除 | I9: 障碍者 | M9: それぞれの人数を入力
A10: 総合譲渡所得（短期） | I10: 特別障碍者
A11: 総合譲渡所得（長期） | I11: 同居特別障碍者
A12: 一時所得 | H12: 配偶者控除 | J12: 一般 | K12: ×
A13: 分離課税短期譲渡所得金額 | B13: 一般 | H13: 配偶者特別控除 | M13: 配偶者の合計所得金額を入力
B14: 軽減 | H14: 扶養控除 | I14: 一般 | M14: それぞれの人数を入力
A15: 分離課税長期譲渡所得金額 | B15: 一般 | I15: 特定扶養親族
B16: 特定 | I16: 老人扶養親族
B17: 軽課 | I17: 同居老人扶養親族
A18: 一般株式等に係る譲渡所得等の金額 | H18: 特定親族特別控除 | K18: 1000000 | M18: 令和7年度新設 親族等の合計所得金額(58万円超123万円以下)を入力
A19: 上場株式等に係る譲渡所得の金額 | H19: 雑損控除
A20: 上場株式等に係る配当所得等の金額 | H20: 医療費控除 | J20: 134037
A21: 先物取引に係る雑所得等の金額 | H21: 寄付金控除 | I21: 特定寄付金 | J21: 13000 | M21: 特定寄付金の金額を入力
A22: 山林所得金額 | I22: ふるさと納税 | J22: 448000 | K22: 48000
A23: 退職所得金額 | H23: 政党等寄付金等特別控除 | I23: 政党等寄付金
I24: 認定NPO法人寄付金 | J24: 13000
I25: 公益社団法人等寄付金
I27: 共同募金・日赤
I28: 条例指定NPO
H30: 基本控除対象寄付合計（住民税） | J30: =SUM(J22,J27,J28) -> 448000 | K30: =SUM(K22,K27,K28) -> 48000
H31: 特例控除対象寄付合計（住民税） | J31: =J22 -> 448000 | K31: =K22 -> 48000
H33: ワンストップ適用フラグ | J33: TRUE | K33: FALSE
H34: 寄付先団体数 | J34: 10 | K34: 1
H35: 所得税申告 | J35: TRUE | K35: FALSE
H37: 特別税額控除の人数
H39: 源泉徴収税額

Sheet 計算結果
A1: 所得税 | T1: 住民税
A4: 損益通算（前期） | L4: 第一表
O5: 前期 | P5: 当期 | Q5: 当期(寄付なし) | V5: 前期 | W5: 当期 | X5: 当期(寄付なし) | AA5: 前期 | AB5: 当期 | AD5: 寄付による減税額
A6: 譲渡・一時所得の損益の通算 | L6: 所得金額 | M6: 総合課税の合計額 | O6: =SUM(J13:J16) -> 13831070 | P6: =SUM(J40:J43) -> 5000000 | Q6: =SUM(J40:J43) -> 5000000 | T6: 指定都市 | V6: FALSE | W6: FALSE | X6: FALSE | Z6: 所得金額合計 | AA6: =SUM(O6,O38,O39) -> 13831070 | AB6: =SUM(P6,P38,P39) -> 5000000 | AD6: 所得税 | AE6: =Q67-P67 -> 7760
A7: 所得の種類 | C7: 差引金額 | E7: 通算後 | G7: 特別控除 | I7: 譲渡・一時の通算後 | T7: 課税総所得金額 | V7: =IF(ROUNDDOWN(AA6-AA24,-3)<0,0,ROUNDDOWN(AA6-AA24,-3)) -> 12563000 | W7: =IF(ROUNDDOWN(AB6-AB24,-3)<0,0,ROUNDDOWN(AB6-AB24,-3)) -> 3530000 | X7: =IF(ROUNDDOWN(AB6-AB24,-3)<0,0,ROUNDDOWN(AB6-AB24,-3)) -> 3530000 | AD7: 住民税 | AE7: =W38 -> 41305
A8: 総合譲渡所得（短期） | C8: =インプット表!C10 -> 0 | E8: =_xlfn.LET( _xlpm.st,C8, _xlpm.lt,C9, _xlpm.pre_st, IF(_xlpm.st*_xlpm.lt<0, IF(ABS(_xlpm.st)>=ABS(_xlpm.lt), _xlpm.st+_xlpm.lt, 0), _xlpm.st), _xlpm.pre_st ) -> 0 | G8: =_xlfn.LET( _xlpm.ps, MAX(0,E8), MIN(500000, _xlpm.ps) ) -> 0 | I8: =_xlfn.LET( _xlpm.short_init, E8 - G8, _xlpm.long_init, E9 - G9, _xlpm.one_init, MAX(0, E10 - G10), _xlpm.need_short, MAX(0, -_xlpm.short_init), _xlpm.use_long_for_short, MIN(MAX(0, _xlpm.long_init), _xlpm.need_short), _xlpm.rem_need_short, _xlpm.need_short - _xlpm.use_long_for_short, _xlpm.use_one_for_short, MIN(_xlpm.one_init, _xlpm.rem_need_short), _xlpm.need_long, MAX(0, -_xlpm.long_init), _xlpm.use_short_for_long, MIN(MAX(0, _xlpm.short_init), _xlpm.need_long), _xlpm.rem_need_long, _xlpm.need_long - _xlpm.use_short_for_long, _xlpm.use_one_for_long, MIN(_xlpm.one_init, _xlpm.rem_need_long), _xlpm.short_after, IF(_xlpm.short_init<0, _xlpm.short_init + _xlpm.use_long_for_short + _xlpm.use_one_for_short, IF(_xlpm.long_init<0, _xlpm.short_init - _xlpm.use_short_for_long, _xlpm.short_init ) ), _xlpm.short_after ) -> 0 | L8: 控除額 | M8: 社会保険料控除 | O8: =インプット表!J2 -> 703890 | P8: =インプット表!K2 -> 630000 | Q8: =インプット表!K2 -> 630000 | T8: 寄付金額 | V8: =インプット表!J30 -> 448000 | W8: =インプット表!K30 -> 48000 | X8: 0 | Z8: 社会保険料控除 | AA8: =O8 -> 703890 | AB8: =P8 -> 630000 | AD8: 合計 | AE8: =SUM(AE6:AE7) -> 49065
A9: 総合譲渡所得（長期） | C9: =インプット表!C11 -> 0 | E9: =_xlfn.LET( _xlpm.st,C8, _xlpm.lt,C9, _xlpm.pre_lt, IF(_xlpm.st*_xlpm.lt<0, IF(ABS(_xlpm.lt)>ABS(_xlpm.st), _xlpm.st+_xlpm.lt, 0), _xlpm.lt), _xlpm.pre_lt ) -> 0 | G9: =_xlfn.LET( _xlpm.ps, MAX(0,E8), _xlpm.pl, MAX(0,E9), _xlpm.pool, 500000 - MIN(500000, _xlpm.ps), MIN(_xlpm.pool, _xlpm.pl) ) -> 0 | I9: =_xlfn.LET( _xlpm.short_init, E8 - G8, _xlpm.long_init, E9 - G9, _xlpm.one_init, MAX(0, E10 - G10), _xlpm.need_short, MAX(0, -_xlpm.short_init), _xlpm.use_long_for_short, MIN(MAX(0, _xlpm.long_init), _xlpm.need_short), _xlpm.need_long, MAX(0, -_xlpm.long_init), _xlpm.use_short_for_long, MIN(MAX(0, _xlpm.short_init), _xlpm.need_long), _xlpm.rem_need_long, _xlpm.need_long - _xlpm.use_short_for_long, _xlpm.use_one_for_long, MIN(_xlpm.one_init, _xlpm.rem_need_long), _xlpm.long_after, IF(_xlpm.short_init<0, _xlpm.long_init - _xlpm.use_long_for_short, IF(_xlpm.long_init<0, _xlpm.long_init + _xlpm.use_short_for_long + _xlpm.use_one_for_long, _xlpm.long_init ) ), _xlpm.long_after ) -> 0 | M9: 小規模企業共済等掛金控除 | O9: =インプット表!J3 -> 0 | P9: =インプット表!K3 -> 0 | Q9: =インプット表!K3 -> 0 | T9: ふるさと納税寄付金額 | V9: =インプット表!J22 -> 448000 | W9: =インプット表!K22 -> 48000 | X9: 0 | Z9: 小規模企業共済等掛金控除 | AA9: =O9 -> 0 | AB9: =P9 -> 0
A10: 一時 | C10: =IF(インプット表!C12<0,0,インプット表!C12) -> 0 | E10: =C10 -> 0 | G10: =_xlfn.LET( _xlpm.pit, MAX(0,E10), MIN(500000, _xlpm.pit) ) -> 0 | I10: =_xlfn.LET( _xlpm.short_init, E8 - G8, _xlpm.long_init, E9 - G9, _xlpm.one_init, MAX(0, E10 - G10), _xlpm.need_short, MAX(0, -_xlpm.short_init), _xlpm.use_long_for_short, MIN(MAX(0, _xlpm.long_init), _xlpm.need_short), _xlpm.rem_need_short, _xlpm.need_short - _xlpm.use_long_for_short, _xlpm.use_one_for_short, MIN(_xlpm.one_init, _xlpm.rem_need_short), _xlpm.need_long, MAX(0, -_xlpm.long_init), _xlpm.use_short_for_long, MIN(MAX(0, _xlpm.short_init), _xlpm.need_long), _xlpm.rem_need_long, _xlpm.need_long - _xlpm.use_short_for_long, _xlpm.use_one_for_long, MIN(_xlpm.one_init, _xlpm.rem_need_long), _xlpm.one_after, IF(_xlpm.short_init<0, _xlpm.one_init - _xlpm.use_one_for_short, IF(_xlpm.long_init<0, _xlpm.one_init - _xlpm.use_one_for_long, _xlpm.one_init ) ), MAX(0, _xlpm.one_after) ) -> 0 | M10: 生命保険料控除 | O10: =インプット表!J4 -> 0 | P10: =インプット表!K4 -> 0 | Q10: =インプット表!K4 -> 0 | T10: 調整控除前所得割額 | Z10: 生命保険料控除 | AA10: =O10 -> 0 | AB10: =P10 -> 0
M11: 地震保険料控除 | O11: =インプット表!J5 -> 0 | P11: =インプット表!K5 -> 0 | Q11: =インプット表!K5 -> 0 | U11: 市 | V11: =V7*IF(V6=TRUE,マスター!$L$4,マスター!$N$4) +O29*IF(V6=TRUE,マスター!$L$5,マスター!$N$5) +O30*IF(V6=TRUE,マスター!$L$6,マスター!$N$6) +O31*IF(V6=TRUE,マスター!$L$7,マスター!$N$7) +MIN(O32, 20000000)*IF(V6=TRUE,マスター!$L$8,マスター!$N$8) +MAX(O32-20000000, 0)*IF(V6=TRUE,マスター!$L$9,マスター!$N$9) +MIN(O33, 60000000)*IF(V6=TRUE,マスター!$L$10,マスター!$N$10) +MAX(O33-60000000, 0)*IF(V6=TRUE,マスター!$L$11,マスター!$N$11) +O34*IF(V6=TRUE,マスター!$L$12,マスター!$N$12) +O35*IF(V6=TRUE,マスター!$L$13,マスター!$N$13) +O36*IF(V6=TRUE,マスター!$L$14,マスター!$N$14) +O37*IF(V6=TRUE,マスター!$L$15,マスター!$N$15) +O38*IF(V6=TRUE,マスター!$L$16,マスター!$N$16) +O39*IF(V6=TRUE,マスター!$L$17,マスター!$N$17) -> 753780 | W11: =W7*IF(W6=TRUE,マスター!$L$4,マスター!$N$4) +P29*IF(W6=TRUE,マスター!$L$5,マスター!$N$5) +P30*IF(W6=TRUE,マスター!$L$6,マスター!$N$6) +P31*IF(W6=TRUE,マスター!$L$7,マスター!$N$7) +MIN(P32, 20000000)*IF(W6=TRUE,マスター!$L$8,マスター!$N$8) +MAX(P32-20000000, 0)*IF(W6=TRUE,マスター!$L$9,マスター!$N$9) +MIN(P33, 60000000)*IF(W6=TRUE,マスター!$L$10,マスター!$N$10) +MAX(P33-60000000, 0)*IF(W6=TRUE,マスター!$L$11,マスター!$N$11) +P34*IF(W6=TRUE,マスター!$L$12,マスター!$N$12) +P35*IF(W6=TRUE,マスター!$L$13,マスター!$N$13) +P36*IF(W6=TRUE,マスター!$L$14,マスター!$N$14) +P37*IF(W6=TRUE,マスター!$L$15,マスター!$N$15) +P38*IF(W6=TRUE,マスター!$L$16,マスター!$N$16) +P39*IF(W6=TRUE,マスター!$L$17,マスター!$N$17) -> 211800 | X11: =X7*IF(X6=TRUE,マスター!$L$4,マスター!$N$4) +Q29*IF(X6=TRUE,マスター!$L$5,マスター!$N$5) +Q30*IF(X6=TRUE,マスター!$L$6,マスター!$N$6) +Q31*IF(X6=TRUE,マスター!$L$7,マスター!$N$7) +MIN(Q32, 20000000)*IF(X6=TRUE,マスター!$L$8,マスター!$N$8) +MAX(Q32-20000000, 0)*IF(X6=TRUE,マスター!$L$9,マスター!$N$9) +MIN(Q33, 60000000)*IF(X6=TRUE,マスター!$L$10,マスター!$N$10) +MAX(Q33-60000000, 0)*IF(X6=TRUE,マスター!$L$11,マスター!$N$11) +Q34*IF(X6=TRUE,マスター!$L$12,マスター!$N$12) +Q35*IF(X6=TRUE,マスター!$L$13,マスター!$N$13) +Q36*IF(X6=TRUE,マスター!$L$14,マスター!$N$14) +Q37*IF(X6=TRUE,マスター!$L$15,マスター!$N$15) +Q38*IF(X6=TRUE,マスター!$L$16,マスター!$N$16) +Q39*IF(X6=TRUE,マスター!$L$17,マスター!$N$17) -> 211800 | Z11: 地震保険料控除 | AA11: =O11 -> 0 | AB11: =P11 -> 0
C12: 通算前 | E12: 第1次通算後 | G12: 第2次通算後 | I12: 第3次通算後 | J12: 所得金額 | M12: 寡婦控除 | O12: =IF(AND(インプット表!$J$6="〇",インプット表!$C$25<=5000000),270000,0) -> 0 | P12: =IF(AND(インプット表!K6="〇",インプット表!$D$25<=5000000),270000,0) -> 0 | Q12: =IF(AND(インプット表!K6="〇",インプット表!$D$25<=5000000),270000,0) -> 0 | U12: 県 | V12: =V7*IF(V6=TRUE,マスター!$M$4,マスター!$O$4) +O29*IF(V6=TRUE,マスター!$M$5,マスター!$O$5) +O30*IF(V6=TRUE,マスター!$M$6,マスター!$O$6) +O31*IF(V6=TRUE,マスター!$M$7,マスター!$O$7) +MIN(O32, 20000000)*IF(V6=TRUE,マスター!$M$8,マスター!$O$8) +MAX(O32-20000000, 0)*IF(V6=TRUE,マスター!$M$9,マスター!$O$9) +MIN(O33, 60000000)*IF(V6=TRUE,マスター!$M$10,マスター!$O$10) +MAX(O33-60000000, 0)*IF(V6=TRUE,マスター!$M$11,マスター!$O$11) +O34*IF(V6=TRUE,マスター!$M$12,マスター!$O$12) +O35*IF(V6=TRUE,マスター!$M$13,マスター!$O$13) +O36*IF(V6=TRUE,マスター!$M$14,マスター!$O$14) +O37*IF(V6=TRUE,マスター!$M$15,マスター!$O$15) +O38*IF(V6=TRUE,マスター!$M$16,マスター!$O$16) +O39*IF(V6=TRUE,マスター!$M$17,マスター!$O$17) -> 502520 | W12: =W7*IF(W6=TRUE,マスター!$M$4,マスター!$O$4) +P29*IF(W6=TRUE,マスター!$M$5,マスター!$O$5) +P30*IF(W6=TRUE,マスター!$M$6,マスター!$O$6) +P31*IF(W6=TRUE,マスター!$M$7,マスター!$O$7) +MIN(P32, 20000000)*IF(W6=TRUE,マスター!$M$8,マスター!$O$8) +MAX(P32-20000000, 0)*IF(W6=TRUE,マスター!$M$9,マスター!$O$9) +MIN(P33, 60000000)*IF(W6=TRUE,マスター!$M$10,マスター!$O$10) +MAX(P33-60000000, 0)*IF(W6=TRUE,マスター!$M$11,マスター!$O$11) +P34*IF(W6=TRUE,マスター!$M$12,マスター!$O$12) +P35*IF(W6=TRUE,マスター!$M$13,マスター!$O$13) +P36*IF(W6=TRUE,マスター!$M$14,マスター!$O$14) +P37*IF(W6=TRUE,マスター!$M$15,マスター!$O$15) +P38*IF(W6=TRUE,マスター!$M$16,マスター!$O$16) +P39*IF(W6=TRUE,マスター!$M$17,マスター!$O$17) -> 141200 | X12: =X7*IF(X6=TRUE,マスター!$M$4,マスター!$O$4) +Q29*IF(X6=TRUE,マスター!$M$5,マスター!$O$5) +Q30*IF(X6=TRUE,マスター!$M$6,マスター!$O$6) +Q31*IF(X6=TRUE,マスター!$M$7,マスター!$O$7) +MIN(Q32, 20000000)*IF(X6=TRUE,マスター!$M$8,マスター!$O$8) +MAX(Q32-20000000, 0)*IF(X6=TRUE,マスター!$M$9,マスター!$O$9) +MIN(Q33, 60000000)*IF(X6=TRUE,マスター!$M$10,マスター!$O$10) +MAX(Q33-60000000, 0)*IF(X6=TRUE,マスター!$M$11,マスター!$O$11) +Q34*IF(X6=TRUE,マスター!$M$12,マスター!$O$12) +Q35*IF(X6=TRUE,マスター!$M$13,マスター!$O$13) +Q36*IF(X6=TRUE,マスター!$M$14,マスター!$O$14) +Q37*IF(X6=TRUE,マスター!$M$15,マスター!$O$15) +Q38*IF(X6=TRUE,マスター!$M$16,マスター!$O$16) +Q39*IF(X6=TRUE,マスター!$M$17,マスター!$O$17) -> 141200 | Z12: 寡婦控除 | AA12: =IF(AND(インプット表!$J$6="〇",インプット表!$C$25<5000000),260000,0) -> 0 | AB12: =IF(AND(インプット表!$K$6="〇",インプット表!$D$25<5000000),260000,0) -> 0
A13: 経常所得 | C13: =SUM(インプット表!C2,インプット表!C3,インプット表!C4,IF(インプット表!C5<0,0,インプット表!C5),IF(インプット表!C6<0,0,インプット表!C6),IF(インプット表!C7<0,0,インプット表!C7),IF(インプット表!C8<0,0,インプット表!C8),IF(インプット表!C9<0,0,インプット表!C9)) -> 13831070 | D13: 第1次 | E13: =_xlfn.LET( _xlpm.econ,C13, _xlpm.shortT,C14, _xlpm.longT,C15, _xlpm.oneTime,C16, _xlpm.econ_pos,MAX(0,_xlpm.econ), _xlpm.lt_neg,MAX(0,-_xlpm.longT), _xlpm.st_neg,MAX(0,-_xlpm.shortT), _xlpm.use_econ,MIN(_xlpm.econ_pos, _xlpm.lt_neg+_xlpm.st_neg), _xlpm.lt_raise,MIN(_xlpm.use_econ, _xlpm.lt_neg), _xlpm.st_raise,MIN(_xlpm.use_econ-_xlpm.lt_raise, _xlpm.st_neg), _xlpm.econ_after, _xlpm.econ-(_xlpm.lt_raise+_xlpm.st_raise), _xlpm.st_after, _xlpm.shortT+_xlpm.st_raise, _xlpm.lt_after, _xlpm.longT+_xlpm.lt_raise, _xlpm.it_after, _xlpm.oneTime, _xlpm.econ_neg,MAX(0,-_xlpm.econ_after), _xlpm.use_from_st,MIN(MAX(0,_xlpm.st_after), _xlpm.econ_neg), _xlpm.use_from_lt,MIN(MAX(0,_xlpm.lt_after), _xlpm.econ_neg-_xlpm.use_from_st), _xlpm.use_from_it,MIN(MAX(0,_xlpm.it_after), _xlpm.econ_neg-_xlpm.use_from_st-_xlpm.use_from_lt), _xlpm.econ_after + _xlpm.use_from_st + _xlpm.use_from_lt + _xlpm.use_from_it ) -> 13831070 | F13: 第2次 | G13: =_xlfn.LET( _xlpm.econ,E13, _xlpm.st,E14, _xlpm.lt,E15, _xlpm.it,E16, _xlpm.forest,E17, _xlpm.forest_pos,MAX(0,_xlpm.forest), _xlpm.forest_neg,MAX(0,-_xlpm.forest), _xlpm.ltNeg,MAX(0,-_xlpm.lt), _xlpm.stNeg,MAX(0,-_xlpm.st), _xlpm.econNeg,MAX(0,-_xlpm.econ), _xlpm.ltPos,MAX(0,_xlpm.lt), _xlpm.stPos,MAX(0,_xlpm.st), _xlpm.econPos,MAX(0,_xlpm.econ), _xlpm.itPos,MAX(0,_xlpm.it), _xlpm.use_lt_pos, MIN(_xlpm.forest_pos, _xlpm.ltNeg), _xlpm.use_st_pos, MIN(_xlpm.forest_pos-_xlpm.use_lt_pos, _xlpm.stNeg), _xlpm.use_econ_pos,MIN(_xlpm.forest_pos-_xlpm.use_lt_pos-_xlpm.use_st_pos, _xlpm.econNeg), _xlpm.econ_when_pos, _xlpm.econ + _xlpm.use_econ_pos, _xlpm.use_from_econ, MIN(_xlpm.econPos, _xlpm.forest_neg), _xlpm.use_from_st, MIN(_xlpm.stPos, _xlpm.forest_neg - _xlpm.use_from_econ), _xlpm.use_from_lt, MIN(_xlpm.ltPos, _xlpm.forest_neg - _xlpm.use_from_econ - _xlpm.use_from_st), _xlpm.use_from_it, MIN(_xlpm.itPos, _xlpm.forest_neg - _xlpm.use_from_econ - _xlpm.use_from_st - _xlpm.use_from_lt), _xlpm.econ_when_neg, _xlpm.econ - _xlpm.use_from_econ, IF(_xlpm.forest>=0, _xlpm.econ_when_pos, _xlpm.econ_when_neg) ) -> 13831070 | H13: 第3次 | I13: =_xlfn.LET( _xlpm.econ,G13, _xlpm.st,G14, _xlpm.lt,G15, _xlpm.it,G16, _xlpm.forest,G17, _xlpm.retire,G18, _xlpm.ret_pos,MAX(0,_xlpm.retire), _xlpm.neg_lt,MAX(0,-_xlpm.lt), _xlpm.neg_st,MAX(0,-_xlpm.st), _xlpm.neg_econ,MAX(0,-_xlpm.econ), _xlpm.neg_for,MAX(0,-_xlpm.forest), _xlpm.use_lt,MIN(_xlpm.ret_pos,_xlpm.neg_lt), _xlpm.use_st,MIN(_xlpm.ret_pos-_xlpm.use_lt,_xlpm.neg_st), _xlpm.use_econ,MIN(_xlpm.ret_pos-_xlpm.use_lt-_xlpm.use_st,_xlpm.neg_econ), _xlpm.use_for,MIN(_xlpm.ret_pos-_xlpm.use_lt-_xlpm.use_st-_xlpm.use_econ,_xlpm.neg_for), _xlpm.econ + _xlpm.use_econ ) -> 13831070 | J13: =I13 -> 13831070 | M13: ひとり親控除 | O13: =IF(AND(インプット表!$J$7="〇",インプット表!$C$25<=5000000),350000,0) -> 0 | P13: =IF(AND(インプット表!K7="〇",インプット表!$D$25<=5000000),350000,0) -> 0 | Q13: =IF(AND(インプット表!K7="〇",インプット表!$D$25<=5000000),350000,0) -> 0 | T13: 調整控除額 | Z13: ひとり親控除 | AA13: =IF(AND(インプット表!$J$7="〇",インプット表!$C$25<5000000),300000,0) -> 0 | AB13: =IF(AND(インプット表!$K$7="〇",インプット表!$D$25<5000000),300000,0) -> 0
A14: 総合譲渡所得（短期） | C14: =I8 -> 0 | E14: =_xlfn.LET( _xlpm.econ,C13, _xlpm.shortT,C14, _xlpm.longT,C15, _xlpm.oneTime,C16, _xlpm.econ_pos,MAX(0,_xlpm.econ), _xlpm.lt_neg,MAX(0,-_xlpm.longT), _xlpm.st_neg,MAX(0,-_xlpm.shortT), _xlpm.use_econ,MIN(_xlpm.econ_pos, _xlpm.lt_neg+_xlpm.st_neg), _xlpm.lt_raise,MIN(_xlpm.use_econ, _xlpm.lt_neg), _xlpm.st_raise,MIN(_xlpm.use_econ-_xlpm.lt_raise, _xlpm.st_neg), _xlpm.econ_after, _xlpm.econ-(_xlpm.lt_raise+_xlpm.st_raise), _xlpm.st_after, _xlpm.shortT+_xlpm.st_raise, _xlpm.econ_neg,MAX(0,-_xlpm.econ_after), _xlpm.use_from_st,MIN(MAX(0,_xlpm.st_after), _xlpm.econ_neg), _xlpm.st_after - _xlpm.use_from_st ) -> 0 | G14: =_xlfn.LET( _xlpm.econ,E13, _xlpm.st,E14, _xlpm.lt,E15, _xlpm.it,E16, _xlpm.forest,E17, _xlpm.forest_pos,MAX(0,_xlpm.forest), _xlpm.forest_neg,MAX(0,-_xlpm.forest), _xlpm.ltNeg,MAX(0,-_xlpm.lt), _xlpm.stNeg,MAX(0,-_xlpm.st), _xlpm.ltPos,MAX(0,_xlpm.lt), _xlpm.stPos,MAX(0,_xlpm.st), _xlpm.itPos,MAX(0,_xlpm.it), _xlpm.econPos,MAX(0,_xlpm.econ), _xlpm.use_lt_pos, MIN(_xlpm.forest_pos, _xlpm.ltNeg), _xlpm.use_st_pos, MIN(_xlpm.forest_pos-_xlpm.use_lt_pos, _xlpm.stNeg), _xlpm.st_when_pos, _xlpm.st + _xlpm.use_st_pos, _xlpm.use_from_econ, MIN(_xlpm.econPos, _xlpm.forest_neg), _xlpm.use_from_st, MIN(_xlpm.stPos, _xlpm.forest_neg - _xlpm.use_from_econ), _xlpm.st_when_neg, _xlpm.st - _xlpm.use_from_st, IF(_xlpm.forest>=0, _xlpm.st_when_pos, _xlpm.st_when_neg) ) -> 0 | I14: =_xlfn.LET( _xlpm.econ,G13, _xlpm.st,G14, _xlpm.lt,G15, _xlpm.it,G16, _xlpm.forest,G17, _xlpm.retire,G18, _xlpm.ret_pos,MAX(0,_xlpm.retire), _xlpm.neg_lt,MAX(0,-_xlpm.lt), _xlpm.neg_st,MAX(0,-_xlpm.st), _xlpm.neg_econ,MAX(0,-_xlpm.econ), _xlpm.neg_for,MAX(0,-_xlpm.forest), _xlpm.use_lt,MIN(_xlpm.ret_pos,_xlpm.neg_lt), _xlpm.use_st,MIN(_xlpm.ret_pos-_xlpm.use_lt,_xlpm.neg_st), _xlpm.st + _xlpm.use_st ) -> 0 | J14: =I14 -> 0 | M14: 勤労学生控除 | O14: =IF(インプット表!$J$8="〇",270000,0) -> 0 | P14: =IF(インプット表!K8="〇",270000,0) -> 0 | Q14: =IF(インプット表!K8="〇",270000,0) -> 0 | U14: 市 | V14: =IF(OR($AA$6>25000000, $V$7<=0), 0, _xlfn.LET( _xlpm.I, $V$7, _xlpm.D, $AA$39 - $AA$38, _xlpm.total, IF(_xlpm.I<=2000000, MIN(_xlpm.D+50000, _xlpm.I) * 0.05, MAX( (_xlpm.D +50000 - (_xlpm.I - 2000000)) * 0.05, 2500 ) ), _xlpm.total * IF($V$6, 4/5, 3/5) ) ) -> 1500 | W14: =IF(W7=0,0,50000*IF(W6=TRUE,マスター!$L$18,マスター!$N$18)) -> 1500 | X14: =IF(X7=0,0,50000*IF(X6=TRUE,マスター!$L$18,マスター!$N$18)) -> 1500 | Z14: 勤労学生控除 | AA14: =IF(インプット表!$J$8="〇",260000,0) -> 0 | AB14: =IF(インプット表!$K$8="〇",260000,0) -> 0
A15: 総合譲渡所得（長期） | C15: =I9 -> 0 | E15: =_xlfn.LET( _xlpm.econ,C13, _xlpm.shortT,C14, _xlpm.longT,C15, _xlpm.oneTime,C16, _xlpm.econ_pos,MAX(0,_xlpm.econ), _xlpm.lt_neg,MAX(0,-_xlpm.longT), _xlpm.st_neg,MAX(0,-_xlpm.shortT), _xlpm.use_econ,MIN(_xlpm.econ_pos, _xlpm.lt_neg+_xlpm.st_neg), _xlpm.lt_raise,MIN(_xlpm.use_econ, _xlpm.lt_neg), _xlpm.st_raise,MIN(_xlpm.use_econ-_xlpm.lt_raise, _xlpm.st_neg), _xlpm.econ_after, _xlpm.econ-(_xlpm.lt_raise+_xlpm.st_raise), _xlpm.lt_after, _xlpm.longT+_xlpm.lt_raise, _xlpm.econ_neg,MAX(0,-_xlpm.econ_after), _xlpm.use_from_st,MIN(MAX(0,_xlpm.shortT+_xlpm.st_raise), _xlpm.econ_neg), _xlpm.use_from_lt,MIN(MAX(0,_xlpm.lt_after), _xlpm.econ_neg-_xlpm.use_from_st), _xlpm.lt_after - _xlpm.use_from_lt ) -> 0 | G15: =_xlfn.LET( _xlpm.econ,E13, _xlpm.st,E14, _xlpm.lt,E15, _xlpm.it,E16, _xlpm.forest,E17, _xlpm.forest_pos,MAX(0,_xlpm.forest), _xlpm.forest_neg,MAX(0,-_xlpm.forest), _xlpm.ltNeg,MAX(0,-_xlpm.lt), _xlpm.stNeg,MAX(0,-_xlpm.st), _xlpm.ltPos,MAX(0,_xlpm.lt), _xlpm.stPos,MAX(0,_xlpm.st), _xlpm.itPos,MAX(0,_xlpm.it), _xlpm.econPos,MAX(0,_xlpm.econ), _xlpm.use_lt_pos, MIN(_xlpm.forest_pos, _xlpm.ltNeg), _xlpm.lt_when_pos, _xlpm.lt + _xlpm.use_lt_pos, _xlpm.use_from_econ, MIN(_xlpm.econPos, _xlpm.forest_neg), _xlpm.use_from_st, MIN(_xlpm.stPos, _xlpm.forest_neg - _xlpm.use_from_econ), _xlpm.use_from_lt, MIN(_xlpm.ltPos, _xlpm.forest_neg - _xlpm.use_from_econ - _xlpm.use_from_st), _xlpm.lt_when_neg, _xlpm.lt - _xlpm.use_from_lt, IF(_xlpm.forest>=0, _xlpm.lt_when_pos, _xlpm.lt_when_neg) ) -> 0 | I15: =_xlfn.LET( _xlpm.econ,G13, _xlpm.st,G14, _xlpm.lt,G15, _xlpm.it,G16, _xlpm.forest,G17, _xlpm.retire,G18, _xlpm.ret_pos,MAX(0,_xlpm.retire), _xlpm.neg_lt,MAX(0,-_xlpm.lt), _xlpm.neg_st,MAX(0,-_xlpm.st), _xlpm.neg_econ,MAX(0,-_xlpm.econ), _xlpm.neg_for,MAX(0,-_xlpm.forest), _xlpm.use_lt,MIN(_xlpm.ret_pos,_xlpm.neg_lt), _xlpm.lt + _xlpm.use_lt ) -> 0 | J15: =I15/2 -> 0 | M15: 障害者控除 | O15: =SUM(インプット表!$J$9*270000,インプット表!$J$10*400000,インプット表!$J$11*750000) -> 0 | P15: =SUM(インプット表!K9*270000,インプット表!K10*400000,インプット表!K11*750000) -> 0 | Q15: =SUM(インプット表!K9*270000,インプット表!K10*400000,インプット表!K11*750000) -> 0 | U15: 県 | V15: =IF(OR($AA$6>25000000, $V$7<=0), 0, _xlfn.LET( _xlpm.I, $V$7, _xlpm.D, $AA$39 - $AA$38, _xlpm.total, IF(_xlpm.I<=2000000, MIN(_xlpm.D +50000, _xlpm.I) * 0.05, MAX( (_xlpm.D + 50000 - (_xlpm.I - 2000000)) * 0.05, 2500 ) ), _xlpm.total * IF($V$6, 1/5, 2/5) ) ) -> 1000 | W15: =IF(W7=0,0,50000*IF(W6=TRUE,マスター!$M$18,マスター!$O$18)) -> 1000 | X15: =IF(X7=0,0,50000*IF(X6=TRUE,マスター!$M$18,マスター!$O$18)) -> 1000 | Z15: 障害者控除 | AA15: =SUM(インプット表!$J$9*260000,インプット表!$J$10*300000,インプット表!$J$11*530000) -> 0 | AB15: =SUM(インプット表!$K$9*260000,インプット表!$K$10*300000,インプット表!$K$11*530000) -> 0
A16: 一時所得 | C16: =I10 -> 0 | E16: =_xlfn.LET( _xlpm.econ,C13, _xlpm.shortT,C14, _xlpm.longT,C15, _xlpm.oneTime,C16, _xlpm.econ_pos,MAX(0,_xlpm.econ), _xlpm.lt_neg,MAX(0,-_xlpm.longT), _xlpm.st_neg,MAX(0,-_xlpm.shortT), _xlpm.use_econ,MIN(_xlpm.econ_pos, _xlpm.lt_neg+_xlpm.st_neg), _xlpm.lt_raise,MIN(_xlpm.use_econ, _xlpm.lt_neg), _xlpm.st_raise,MIN(_xlpm.use_econ-_xlpm.lt_raise, _xlpm.st_neg), _xlpm.econ_after, _xlpm.econ-(_xlpm.lt_raise+_xlpm.st_raise), _xlpm.st_after, _xlpm.shortT+_xlpm.st_raise, _xlpm.lt_after, _xlpm.longT+_xlpm.lt_raise, _xlpm.it_after, _xlpm.oneTime, _xlpm.econ_neg,MAX(0,-_xlpm.econ_after), _xlpm.use_from_st,MIN(MAX(0,_xlpm.st_after), _xlpm.econ_neg), _xlpm.use_from_lt,MIN(MAX(0,_xlpm.lt_after), _xlpm.econ_neg-_xlpm.use_from_st), _xlpm.use_from_it,MIN(MAX(0,_xlpm.it_after), _xlpm.econ_neg-_xlpm.use_from_st-_xlpm.use_from_lt), MAX(0, _xlpm.it_after - _xlpm.use_from_it) ) -> 0 | G16: =_xlfn.LET( _xlpm.econ,E13, _xlpm.st,E14, _xlpm.lt,E15, _xlpm.it,E16, _xlpm.forest,E17, _xlpm.forest_pos,MAX(0,_xlpm.forest), _xlpm.forest_neg,MAX(0,-_xlpm.forest), _xlpm.ltNeg,MAX(0,-_xlpm.lt), _xlpm.stNeg,MAX(0,-_xlpm.st), _xlpm.econNeg,MAX(0,-_xlpm.econ), _xlpm.ltPos,MAX(0,_xlpm.lt), _xlpm.stPos,MAX(0,_xlpm.st), _xlpm.econPos,MAX(0,_xlpm.econ), _xlpm.itPos,MAX(0,_xlpm.it), _xlpm.use_lt_pos, MIN(_xlpm.forest_pos, _xlpm.ltNeg), _xlpm.use_st_pos, MIN(_xlpm.forest_pos-_xlpm.use_lt_pos, _xlpm.stNeg), _xlpm.use_econ_pos,MIN(_xlpm.forest_pos-_xlpm.use_lt_pos-_xlpm.use_st_pos, _xlpm.econNeg), _xlpm.it_when_pos, _xlpm.it, _xlpm.use_from_econ, MIN(_xlpm.econPos, _xlpm.forest_neg), _xlpm.use_from_st, MIN(_xlpm.stPos, _xlpm.forest_neg - _xlpm.use_from_econ), _xlpm.use_from_lt, MIN(_xlpm.ltPos, _xlpm.forest_neg - _xlpm.use_from_econ - _xlpm.use_from_st), _xlpm.use_from_it, MIN(_xlpm.itPos, _xlpm.forest_neg - _xlpm.use_from_econ - _xlpm.use_from_st - _xlpm.use_from_lt), _xlpm.it_when_neg, MAX(0, _xlpm.it - _xlpm.use_from_it), IF(_xlpm.forest>=0, _xlpm.it_when_pos, _xlpm.it_when_neg) ) -> 0 | I16: =_xlfn.LET( _xlpm.it,G16, _xlpm.it ) -> 0 | J16: =I16/2 -> 0 | M16: 配偶者控除 | O16: {=_xlfn.IFS( インプット表!$J$12="",0, N(SUM(O6,O29:O39))>10000000, 0, LEFT(TRIM(インプット表!$J$12),1)="老", INDEX({480000,320000,160000}, MATCH(SUM(O6,O29:O39),{0,9000001,9500001},1)), LEFT(TRIM(インプット表!$J$12),1)="一", INDEX({380000,260000,130000}, MATCH(SUM(O6,O29:O39),{0,9000001,9500001},1)), LEFT(TRIM(インプット表!$J$12),1)="×", 0 )} -> 0 | P16: {=_xlfn.IFS( インプット表!$K$12="",0, N(SUM(P6,P29:P39))>10000000, 0, LEFT(TRIM(インプット表!$K$12),1)="老", INDEX({480000,320000,160000}, MATCH(SUM(P6,P29:P39),{0,9000001,9500001},1)), LEFT(TRIM(インプット表!$K$12),1)="一", INDEX({380000,260000,130000}, MATCH(SUM(P6,P29:P39),{0,9000001,9500001},1)), LEFT(TRIM(インプット表!$K$12),1)="×", 0 )} -> 0 | Q16: {=_xlfn.IFS( インプット表!$K$12="",0, N(SUM(Q6,Q29:Q39))>10000000, 0, LEFT(TRIM(インプット表!$K$12),1)="老", INDEX({480000,320000,160000}, MATCH(SUM(Q6,Q29:Q39),{0,9000001,9500001},1)), LEFT(TRIM(インプット表!$K$12),1)="一", INDEX({380000,260000,130000}, MATCH(SUM(Q6,Q29:Q39),{0,9000001,9500001},1)), LEFT(TRIM(インプット表!$K$12),1)="×", 0 )} -> 0 | T16: 調整控除後所得割額 | Z16: 配偶者控除 | AA16: {=_xlfn.IFS( N(SUM(O6,O29:O39))>10000000, 0, LEFT(TRIM(インプット表!$J$12),1)="老", INDEX({380000,260000,130000}, MATCH(SUM(O6,O29:O39),{0,9000001,9500001},1)), LEFT(TRIM(インプット表!$J$12),1)="一", INDEX({330000,220000,110000}, MATCH(SUM(O6,O29:O39),{0,9000001,9500001},1)), LEFT(TRIM(インプット表!$J$12),1)="×", 0 )} -> 0 | AB16: {=_xlfn.IFS( N(SUM(P6,P29:P39))>10000000, 0, LEFT(TRIM(インプット表!$K$12),1)="老", INDEX({380000,260000,130000}, MATCH(SUM(P6,P29:P39),{0,9000001,9500001},1)), LEFT(TRIM(インプット表!$K$12),1)="一", INDEX({330000,220000,110000}, MATCH(SUM(P6,P29:P39),{0,9000001,9500001},1)), LEFT(TRIM(インプット表!$K$12),1)="×", 0 )} -> 0
A17: 山林所得金額 | C17: =インプット表!C22 -> 0 | E17: =C17 -> 0 | G17: =_xlfn.LET( _xlpm.econ,E13, _xlpm.st,E14, _xlpm.lt,E15, _xlpm.it,E16, _xlpm.forest,E17, _xlpm.forest_pos,MAX(0,_xlpm.forest), _xlpm.forest_neg,MAX(0,-_xlpm.forest), _xlpm.ltNeg,MAX(0,-_xlpm.lt), _xlpm.stNeg,MAX(0,-_xlpm.st), _xlpm.econNeg,MAX(0,-_xlpm.econ), _xlpm.ltPos,MAX(0,_xlpm.lt), _xlpm.stPos,MAX(0,_xlpm.st), _xlpm.econPos,MAX(0,_xlpm.econ), _xlpm.itPos,MAX(0,_xlpm.it), _xlpm.use_lt_pos, MIN(_xlpm.forest_pos, _xlpm.ltNeg), _xlpm.use_st_pos, MIN(_xlpm.forest_pos-_xlpm.use_lt_pos, _xlpm.stNeg), _xlpm.use_econ_pos,MIN(_xlpm.forest_pos-_xlpm.use_lt_pos-_xlpm.use_st_pos, _xlpm.econNeg), _xlpm.forest_after_pos, _xlpm.forest - (_xlpm.use_lt_pos + _xlpm.use_st_pos + _xlpm.use_econ_pos), _xlpm.use_from_econ, MIN(_xlpm.econPos, _xlpm.forest_neg), _xlpm.use_from_st, MIN(_xlpm.stPos, _xlpm.forest_neg - _xlpm.use_from_econ), _xlpm.use_from_lt, MIN(_xlpm.ltPos, _xlpm.forest_neg - _xlpm.use_from_econ - _xlpm.use_from_st), _xlpm.use_from_it, MIN(_xlpm.itPos, _xlpm.forest_neg - _xlpm.use_from_econ - _xlpm.use_from_st - _xlpm.use_from_lt), _xlpm.forest_after_neg, _xlpm.forest + (_xlpm.use_from_econ + _xlpm.use_from_st + _xlpm.use_from_lt + _xlpm.use_from_it), IF(_xlpm.forest>=0, _xlpm.forest_after_pos, _xlpm.forest_after_neg) ) -> 0 | I17: =_xlfn.LET( _xlpm.econ,G13, _xlpm.st,G14, _xlpm.lt,G15, _xlpm.it,G16, _xlpm.forest,G17, _xlpm.retire,G18, _xlpm.ret_pos,MAX(0,_xlpm.retire), _xlpm.neg_lt,MAX(0,-_xlpm.lt), _xlpm.neg_st,MAX(0,-_xlpm.st), _xlpm.neg_econ,MAX(0,-_xlpm.econ), _xlpm.neg_for,MAX(0,-_xlpm.forest), _xlpm.use_lt,MIN(_xlpm.ret_pos,_xlpm.neg_lt), _xlpm.use_st,MIN(_xlpm.ret_pos-_xlpm.use_lt,_xlpm.neg_st), _xlpm.use_econ,MIN(_xlpm.ret_pos-_xlpm.use_lt-_xlpm.use_st,_xlpm.neg_econ), _xlpm.use_for,MIN(_xlpm.ret_pos-_xlpm.use_lt-_xlpm.use_st-_xlpm.use_econ,_xlpm.neg_for), _xlpm.forest + _xlpm.use_for ) -> 0 | J17: =I17 -> 0 | M17: 配偶者特別控除 | O17: {=IF( OR(_xlfn.NUMBERVALUE(SUM(O6,O29:O39))>10000000, _xlfn.NUMBERVALUE(インプット表!$J$13)<=480000, _xlfn.NUMBERVALUE(インプット表!$J$13)>1330000 ), 0, INDEX( CHOOSE( LOOKUP(_xlfn.NUMBERVALUE(SUM(O6,O29:O39)),{0,9000001,9500001},{1,2,3}), {380000;360000;310000;260000;210000;160000;110000;60000;30000}, {260000;240000;210000;180000;140000;110000;80000;40000;20000}, {130000;120000;110000;90000;70000;60000;40000;20000;10000} ), LOOKUP(_xlfn.NUMBERVALUE(SUM(O6,O29:O39)), {480001;950001;1000001;1050001;1100001;1150001;1200001;1250001;1300001}, {1;2;3;4;5;6;7;8;9} ) ) )} -> 0 | P17: {=IF( OR(_xlfn.NUMBERVALUE(SUM(P6,P29:P39))>10000000, _xlfn.NUMBERVALUE(インプット表!$K$13)<=480000, _xlfn.NUMBERVALUE(インプット表!$K$13)>1330000 ), 0, INDEX( CHOOSE( LOOKUP(_xlfn.NUMBERVALUE(SUM(P6,P29:P39)),{0,9000001,9500001},{1,2,3}), {380000;360000;310000;260000;210000;160000;110000;60000;30000}, {260000;240000;210000;180000;140000;110000;80000;40000;20000}, {130000;120000;110000;90000;70000;60000;40000;20000;10000} ), LOOKUP(_xlfn.NUMBERVALUE(SUM(P6,P29:P39)), {480001;950001;1000001;1050001;1100001;1150001;1200001;1250001;1300001}, {1;2;3;4;5;6;7;8;9} ) ) )} -> 0 | Q17: {=IF( OR(_xlfn.NUMBERVALUE(SUM(Q6,Q29:Q39))>10000000, _xlfn.NUMBERVALUE(インプット表!$K$13)<=480000, _xlfn.NUMBERVALUE(インプット表!$K$13)>1330000 ), 0, INDEX( CHOOSE( LOOKUP(_xlfn.NUMBERVALUE(SUM(Q6,Q29:Q39)),{0,9000001,9500001},{1,2,3}), {380000;360000;310000;260000;210000;160000;110000;60000;30000}, {260000;240000;210000;180000;140000;110000;80000;40000;20000}, {130000;120000;110000;90000;70000;60000;40000;20000;10000} ), LOOKUP(_xlfn.NUMBERVALUE(SUM(Q6,Q29:Q39)), {480001;950001;1000001;1050001;1100001;1150001;1200001;1250001;1300001}, {1;2;3;4;5;6;7;8;9} ) ) )} -> 0 | U17: 市 | V17: =V11-V14 -> 752280 | W17: =W11-W14 -> 210300 | X17: =X11-X14 -> 210300 | Z17: 配偶者特別控除 | AA17: {=IF( OR(_xlfn.NUMBERVALUE(インプット表!$C$25)>10000000, _xlfn.NUMBERVALUE(インプット表!$J$13)<=480000, _xlfn.NUMBERVALUE(インプット表!$J$13)>1330000 ), 0, INDEX( CHOOSE( LOOKUP(_xlfn.NUMBERVALUE(インプット表!$C$25),{0,9000001,9500001},{1,2,3}), {330000;330000;310000;260000;210000;160000;110000;60000;30000}, {220000;220000;210000;180000;140000;110000;80000;40000;20000}, {110000;110000;110000;90000;70000;60000;40000;20000;10000} ), LOOKUP(_xlfn.NUMBERVALUE(インプット表!$J$13), {480001;950001;1000001;1050001;1100001;1150001;1200001;1250001;1300001}, {1;2;3;4;5;6;7;8;9} ) ) )} -> 0 | AB17: {=IF( OR(_xlfn.NUMBERVALUE(インプット表!$D$25)>10000000, _xlfn.NUMBERVALUE(インプット表!$K$13)<=480000, _xlfn.NUMBERVALUE(インプット表!$K$13)>1330000 ), 0, INDEX( CHOOSE( LOOKUP(_xlfn.NUMBERVALUE(インプット表!$D$25),{0,9000001,9500001},{1,2,3}), {330000;330000;310000;260000;210000;160000;110000;60000;30000}, {220000;220000;210000;180000;140000;110000;80000;40000;20000}, {110000;110000;110000;90000;70000;60000;40000;20000;10000} ), LOOKUP(_xlfn.NUMBERVALUE(インプット表!$K$13), {480001;950001;1000001;1050001;1100001;1150001;1200001;1250001;1300001}, {1;2;3;4;5;6;7;8;9} ) ) )} -> 0
A18: 退職所得金額 | C18: =IF(インプット表!C23<0,0,インプット表!C23) -> 0 | E18: =C18 -> 0 | G18: =E18 -> 0 | I18: =_xlfn.LET( _xlpm.econ,G13, _xlpm.st,G14, _xlpm.lt,G15, _xlpm.it,G16, _xlpm.forest,G17, _xlpm.retire,G18, _xlpm.ret_pos,MAX(0,_xlpm.retire), _xlpm.neg_lt,MAX(0,-_xlpm.lt), _xlpm.neg_st,MAX(0,-_xlpm.st), _xlpm.neg_econ,MAX(0,-_xlpm.econ), _xlpm.neg_for,MAX(0,-_xlpm.forest), _xlpm.use_lt,MIN(_xlpm.ret_pos,_xlpm.neg_lt), _xlpm.use_st,MIN(_xlpm.ret_pos-_xlpm.use_lt,_xlpm.neg_st), _xlpm.use_econ,MIN(_xlpm.ret_pos-_xlpm.use_lt-_xlpm.use_st,_xlpm.neg_econ), _xlpm.use_for,MIN(_xlpm.ret_pos-_xlpm.use_lt-_xlpm.use_st-_xlpm.use_econ,_xlpm.neg_for), _xlpm.retire - (_xlpm.use_lt + _xlpm.use_st + _xlpm.use_econ + _xlpm.use_for) ) -> 0 | J18: =I18 -> 0 | M18: 扶養控除 | O18: =SUM(インプット表!$J$14*380000,インプット表!$J$15*630000,インプット表!$J$16*480000,インプット表!$J$17*580000) -> 0 | P18: =SUM(インプット表!K14*380000,インプット表!K15*630000,インプット表!K16*480000,インプット表!K17*580000) -> 0 | Q18: =SUM(インプット表!K14*380000,インプット表!K15*630000,インプット表!K16*480000,インプット表!K17*580000) -> 0 | U18: 県 | V18: =V12-V15 -> 501520 | W18: =W12-W15 -> 140200 | X18: =X12-X15 -> 140200 | Z18: 扶養控除 | AA18: =SUM(インプット表!$J$14*330000,インプット表!$J$15*450000,インプット表!$J$16*380000,インプット表!$J$17*450000) -> 0 | AB18: =SUM(インプット表!$K$14*330000,インプット表!$K$15*450000,インプット表!$K$16*380000,インプット表!$K$17*450000) -> 0
I19: 所得金額の合計額 | J19: =SUM(J13:J18) -> 13831070 | M19: 特定親族特別控除 | O19: {=IF(O6=0,0,INDEX({0,630000,610000,510000,410000,310000,210000,110000,60000,30000,0}, MATCH(_xlfn.NUMBERVALUE(インプット表!J18),{0,580001,850001,900001,950001,100000,1050001,1100001,1150001,1200001,1230001},1)))} -> 0 | P19: {=IF(P6=0,0,INDEX({0,630000,610000,510000,410000,310000,210000,110000,60000,30000,0}, MATCH(_xlfn.NUMBERVALUE(インプット表!K18),{0,580001,850001,900001,950001,1000001,1050001,1100001,1150001,1200001,1230001},1)))} -> 410000 | Q19: {=IF(Q6=0,0,INDEX({0,630000,610000,510000,410000,310000,210000,110000,60000,30000,0}, MATCH(_xlfn.NUMBERVALUE(インプット表!K18),{0,580001,850001,900001,950001,1000001,1050001,1100001,1150001,1200001,1230001},1)))} -> 410000 | U19: 合計 | V19: =SUM(V17:V18) -> 1253800 | W19: =SUM(W17:W18) -> 350500 | X19: =SUM(X17:X18) -> 350500 | Z19: 特定親族特別控除 | AA19: {=IF(AA6=0,0,INDEX({0,630000,610000,510000,410000,310000,210000,110000,60000,30000,0}, MATCH(_xlfn.NUMBERVALUE(インプット表!J18),{0,580001,850001,900001,950001,1000001,1050001,1100001,1150001,1200001,1230001},1)))} -> 0 | AB19: {=IF(AB6=0,0,INDEX({0,450000,450000,450000,410000,310000,210000,110000,60000,30000,0}, MATCH(_xlfn.NUMBERVALUE(インプット表!K18),{0,580001,850001,900001,950001,1000001,1050001,1100001,1150001,1200001,1230001},1)))} -> 410000
M20: 基礎控除 | O20: {=IF(O6=0,0,INDEX({950000,880000,680000,630000,580000,480000,320000,160000,0}, MATCH(_xlfn.NUMBERVALUE(SUM(O6,O29:O39)),{0,1320001,3360001,4890001,6550001,23500001,24000001,24500001,25000001},1)))} -> 580000 | P20: {=IF(P6=0,0,INDEX({950000,880000,680000,630000,580000,480000,320000,160000,0}, MATCH(_xlfn.NUMBERVALUE(SUM(P6,P29:P39)),{0,1320001,3360001,4890001,6550001,23500001,24000001,24500001,25000001},1)))} -> 630000 | Q20: {=IF(Q6=0,0,INDEX({950000,880000,680000,630000,580000,480000,320000,160000,0}, MATCH(_xlfn.NUMBERVALUE(SUM(Q6,Q29:Q39)),{0,1320001,3360001,4890001,6550001,23500001,24000001,24500001,25000001},1)))} -> 630000 | T20: 基本控除額 | Z20: 基礎控除 | AA20: {=INDEX({430000,290000,150000,0}, MATCH(_xlfn.NUMBERVALUE(SUM(AA6,O29:O39)), {0,24000001,24500001,25000001}, 1))} -> 430000 | AB20: {=INDEX({430000,290000,150000,0}, MATCH(_xlfn.NUMBERVALUE(SUM(AB6,P29:P39)), {0,24000001,24500001,25000001}, 1))} -> 430000
A21: 分離課税短期譲渡所得金額 | B21: 一般 | C21: =インプット表!C13 -> 0 | E21: =_xlfn.LET( _xlpm.short_general, C21, _xlpm.short_reduced, C22, _xlpm.short_general_after, IF(AND(_xlpm.short_general>=0, _xlpm.short_reduced<0), _xlpm.short_general - MIN(_xlpm.short_general, -_xlpm.short_reduced), IF(AND(_xlpm.short_general<0, _xlpm.short_reduced>=0), _xlpm.short_general + MIN(_xlpm.short_reduced, -_xlpm.short_general), _xlpm.short_general ) ), _xlpm.short_general_after ) -> 0 | G21: =_xlfn.LET( _xlpm.s_general, E21, _xlpm.s_reduced, E22, _xlpm.l_general, E23, _xlpm.l_reduced, E24, _xlpm.l_light, E25, _xlpm.short_need, MAX(0, -(MIN(0, _xlpm.s_general) + MIN(0, _xlpm.s_reduced))), _xlpm.long_need, MAX(0, -(MIN(0, _xlpm.l_general) + MIN(0, _xlpm.l_reduced) + MIN(0, _xlpm.l_light))), _xlpm.give_lg, IF(AND(_xlpm.short_need>0, _xlpm.long_need=0), MIN(MAX(0, _xlpm.l_general), _xlpm.short_need), 0), _xlpm.rem_s1, IF(AND(_xlpm.short_need>0, _xlpm.long_need=0), _xlpm.short_need - _xlpm.give_lg, 0), _xlpm.give_lr, IF(AND(_xlpm.short_need>0, _xlpm.long_need=0), MIN(MAX(0, _xlpm.l_reduced), _xlpm.rem_s1), 0), _xlpm.rem_s2, IF(AND(_xlpm.short_need>0, _xlpm.long_need=0), _xlpm.rem_s1 - _xlpm.give_lr, 0), _xlpm.give_ll, IF(AND(_xlpm.short_need>0, _xlpm.long_need=0), MIN(MAX(0, _xlpm.l_light), _xlpm.rem_s2), 0), _xlpm.total_to_short, _xlpm.give_lg + _xlpm.give_lr + _xlpm.give_ll, _xlpm.inc_s_general, MIN(MAX(0, -_xlpm.s_general), _xlpm.total_to_short), _xlpm.take_sg, IF(AND(_xlpm.long_need>0, _xlpm.short_need=0), MIN(MAX(0, _xlpm.s_general), _xlpm.long_need), 0), _xlpm.rem_l1, IF(AND(_xlpm.long_need>0, _xlpm.short_need=0), _xlpm.long_need - _xlpm.take_sg, 0), _xlpm.take_sr, IF(AND(_xlpm.long_need>0, _xlpm.short_need=0), MIN(MAX(0, _xlpm.s_reduced), _xlpm.rem_l1), 0), _xlpm.s_general + _xlpm.inc_s_general - _xlpm.take_sg ) -> 0 | M21: 控除小計 | O21: =SUM(O8:O20) -> 1283890 | P21: =SUM(P8:P20) -> 1670000 | Q21: =SUM(Q8:Q20) -> 1670000 | U21: 市 | V21: =IF(N(インプット表!$J$30)<=2000,0, (MIN(N(インプット表!$J$30), N(AA6)*0.3)-2000) *IF($V$6=TRUE, マスター!$L$19, マスター!$N$19)) -> 26760 | W21: =IF(N(インプット表!$K$30)<=2000,0, (MIN(N(インプット表!$K$30), SUM(Q42:Q48)*0.3)-2000) *IF($W$6=TRUE, マスター!$L$19, マスター!$N$19)) -> 2760 | X21: =IF( N(インプット表!$K$30 - インプット表!$K$22) <= 2000, 0, ( MIN( N(インプット表!$K$30 - インプット表!$K$22), N(AB6)*0.3 ) - 2000 ) * IF($W$6, マスター!$L$19, マスター!$N$19) ) -> 0 | Z21: 雑損控除 | AA21: =O22 -> 0 | AB21: =P22 -> 0
B22: 軽減 | C22: =インプット表!C14 -> 0 | E22: =_xlfn.LET( _xlpm.short_general, C21, _xlpm.short_reduced, C22, _xlpm.short_reduced_after, IF(AND(_xlpm.short_general>=0, _xlpm.short_reduced<0), _xlpm.short_reduced + MIN(_xlpm.short_general, -_xlpm.short_reduced), IF(AND(_xlpm.short_general<0, _xlpm.short_reduced>=0), _xlpm.short_reduced - MIN(_xlpm.short_reduced, -_xlpm.short_general), _xlpm.short_reduced ) ), _xlpm.short_reduced_after ) -> 0 | G22: =_xlfn.LET( _xlpm.s_general, E21, _xlpm.s_reduced, E22, _xlpm.l_general, E23, _xlpm.l_reduced, E24, _xlpm.l_light, E25, _xlpm.short_need, MAX(0, -(MIN(0, _xlpm.s_general) + MIN(0, _xlpm.s_reduced))), _xlpm.long_need, MAX(0, -(MIN(0, _xlpm.l_general) + MIN(0, _xlpm.l_reduced) + MIN(0, _xlpm.l_light))), _xlpm.give_lg, IF(AND(_xlpm.short_need>0, _xlpm.long_need=0), MIN(MAX(0, _xlpm.l_general), _xlpm.short_need), 0), _xlpm.rem_s1, IF(AND(_xlpm.short_need>0, _xlpm.long_need=0), _xlpm.short_need - _xlpm.give_lg, 0), _xlpm.give_lr, IF(AND(_xlpm.short_need>0, _xlpm.long_need=0), MIN(MAX(0, _xlpm.l_reduced), _xlpm.rem_s1), 0), _xlpm.rem_s2, IF(AND(_xlpm.short_need>0, _xlpm.long_need=0), _xlpm.rem_s1 - _xlpm.give_lr, 0), _xlpm.give_ll, IF(AND(_xlpm.short_need>0, _xlpm.long_need=0), MIN(MAX(0, _xlpm.l_light), _xlpm.rem_s2), 0), _xlpm.total_to_short, _xlpm.give_lg + _xlpm.give_lr + _xlpm.give_ll, _xlpm.inc_s_general, MIN(MAX(0, -_xlpm.s_general), _xlpm.total_to_short), _xlpm.inc_s_reduced, MIN(MAX(0, -_xlpm.s_reduced), _xlpm.total_to_short - _xlpm.inc_s_general), _xlpm.take_sg, IF(AND(_xlpm.long_need>0, _xlpm.short_need=0), MIN(MAX(0, _xlpm.s_general), _xlpm.long_need), 0), _xlpm.rem_l1, IF(AND(_xlpm.long_need>0, _xlpm.short_need=0), _xlpm.long_need - _xlpm.take_sg, 0), _xlpm.take_sr, IF(AND(_xlpm.long_need>0, _xlpm.short_need=0), MIN(MAX(0, _xlpm.s_reduced), _xlpm.rem_l1), 0), _xlpm.s_reduced + _xlpm.inc_s_reduced - _xlpm.take_sr ) -> 0 | M22: 雑損控除 | O22: =インプット表!J19 -> 0 | P22: =インプット表!K19 -> 0 | Q22: =インプット表!K19 -> 0 | U22: 県 | V22: =IF(N(インプット表!$J$30)<=2000,0, (MIN(N(インプット表!$J$30), N(AA6)*0.3)-2000) *IF($V$6=TRUE, マスター!$M$19, マスター!$O$19)) -> 17840 | W22: =IF(N(インプット表!$K$30)<=2000,0, (MIN(N(インプット表!$K$30), SUM(Q42:Q48)*0.3)-2000) *IF($W$6=TRUE, マスター!$M$19, マスター!$O$19)) -> 1840 | X22: =IF( N(インプット表!$K$30 - インプット表!$K$22) <= 2000, 0, ( MIN( N(インプット表!$K$30 - インプット表!$K$22), N(AB6)*0.3 ) - 2000 ) * IF($W$6, マスター!$M$19, マスター!$O$19) ) -> 0 | Z22: 医療費控除 | AA22: =O23 -> 134037 | AB22: =P23 -> 0
A23: 分離課税長期譲渡所得金額 | B23: 一般 | C23: =インプット表!C15 -> 0 | E23: =_xlfn.LET( _xlpm.long_general, C23, _xlpm.long_reduced, C24, _xlpm.long_light, C25, _xlpm.need_general, MAX(0, -_xlpm.long_general), _xlpm.move_reduced_to_general, MIN(MAX(0, _xlpm.long_reduced), _xlpm.need_general), _xlpm.lg_a, _xlpm.long_general + _xlpm.move_reduced_to_general, _xlpm.lr_a, _xlpm.long_reduced - _xlpm.move_reduced_to_general, _xlpm.ll_a, _xlpm.long_light, _xlpm.need_general_2, MAX(0, -_xlpm.lg_a), _xlpm.move_light_to_general, MIN(MAX(0, _xlpm.ll_a), _xlpm.need_general_2), _xlpm.lg_b, _xlpm.lg_a + _xlpm.move_light_to_general, _xlpm.lr_b, _xlpm.lr_a, _xlpm.ll_b, _xlpm.ll_a - _xlpm.move_light_to_general, _xlpm.need_reduced, MAX(0, -_xlpm.lr_b), _xlpm.move_general_to_reduced, MIN(MAX(0, _xlpm.lg_b), _xlpm.need_reduced), _xlpm.lg_c, _xlpm.lg_b - _xlpm.move_general_to_reduced, _xlpm.lr_c, _xlpm.lr_b + _xlpm.move_general_to_reduced, _xlpm.need_reduced_2, MAX(0, -_xlpm.lr_c), _xlpm.move_light_to_reduced, MIN(MAX(0, _xlpm.ll_b), _xlpm.need_reduced_2), _xlpm.lg_d, _xlpm.lg_c, _xlpm.lr_d, _xlpm.lr_c + _xlpm.move_light_to_reduced, _xlpm.ll_c, _xlpm.ll_b - _xlpm.move_light_to_reduced, _xlpm.need_light, MAX(0, -_xlpm.ll_c), _xlpm.move_general_to_light, MIN(MAX(0, _xlpm.lg_d), _xlpm.need_light), _xlpm.lg_e, _xlpm.lg_d - _xlpm.move_general_to_light, _xlpm.ll_d, _xlpm.ll_c + _xlpm.move_general_to_light, _xlpm.need_light_2, MAX(0, -_xlpm.ll_d), _xlpm.move_reduced_to_light, MIN(MAX(0, _xlpm.lr_d), _xlpm.need_light_2), _xlpm.lg_e ) -> 0 | G23: =_xlfn.LET( _xlpm.s_general, E21, _xlpm.s_reduced, E22, _xlpm.l_general, E23, _xlpm.l_reduced, E24, _xlpm.l_light, E25, _xlpm.short_need, MAX(0, -(MIN(0, _xlpm.s_general) + MIN(0, _xlpm.s_reduced))), _xlpm.long_need, MAX(0, -(MIN(0, _xlpm.l_general) + MIN(0, _xlpm.l_reduced) + MIN(0, _xlpm.l_light))), _xlpm.give_lg, IF(AND(_xlpm.short_need>0, _xlpm.long_need=0), MIN(MAX(0, _xlpm.l_general), _xlpm.short_need), 0), _xlpm.take_sg, IF(AND(_xlpm.long_need>0, _xlpm.short_need=0), MIN(MAX(0, _xlpm.s_general), _xlpm.long_need), 0), _xlpm.rem_l1, IF(AND(_xlpm.long_need>0, _xlpm.short_need=0), _xlpm.long_need - _xlpm.take_sg, 0), _xlpm.take_sr, IF(AND(_xlpm.long_need>0, _xlpm.short_need=0), MIN(MAX(0, _xlpm.s_reduced), _xlpm.rem_l1), 0), _xlpm.inc_l_general, MIN(MAX(0, -_xlpm.l_general), _xlpm.take_sg + _xlpm.take_sr), _xlpm.l_general - _xlpm.give_lg + _xlpm.inc_l_general ) -> 0 | M23: 医療費控除 | O23: =インプット表!J20 -> 134037 | P23: =インプット表!K20 -> 0 | Q23: =インプット表!K20 -> 0 | T23: 特例控除額
B24: 特定 | C24: =インプット表!C16 -> 0 | E24: =_xlfn.LET( _xlpm.long_general, C23, _xlpm.long_reduced, C24, _xlpm.long_light, C25, _xlpm.need_general, MAX(0, -_xlpm.long_general), _xlpm.move_reduced_to_general, MIN(MAX(0, _xlpm.long_reduced), _xlpm.need_general), _xlpm.lg_a, _xlpm.long_general + _xlpm.move_reduced_to_general, _xlpm.lr_a, _xlpm.long_reduced - _xlpm.move_reduced_to_general, _xlpm.ll_a, _xlpm.long_light, _xlpm.need_general_2, MAX(0, -_xlpm.lg_a), _xlpm.move_light_to_general, MIN(MAX(0, _xlpm.ll_a), _xlpm.need_general_2), _xlpm.lg_b, _xlpm.lg_a + _xlpm.move_light_to_general, _xlpm.lr_b, _xlpm.lr_a, _xlpm.ll_b, _xlpm.ll_a - _xlpm.move_light_to_general, _xlpm.need_reduced, MAX(0, -_xlpm.lr_b), _xlpm.move_general_to_reduced, MIN(MAX(0, _xlpm.lg_b), _xlpm.need_reduced), _xlpm.lg_c, _xlpm.lg_b - _xlpm.move_general_to_reduced, _xlpm.lr_c, _xlpm.lr_b + _xlpm.move_general_to_reduced, _xlpm.need_reduced_2, MAX(0, -_xlpm.lr_c), _xlpm.move_light_to_reduced, MIN(MAX(0, _xlpm.ll_b), _xlpm.need_reduced_2), _xlpm.lr_d, _xlpm.lr_c + _xlpm.move_light_to_reduced, _xlpm.lr_d ) -> 0 | G24: =_xlfn.LET( _xlpm.s_general, E21, _xlpm.s_reduced, E22, _xlpm.l_general, E23, _xlpm.l_reduced, E24, _xlpm.l_light, E25, _xlpm.short_need, MAX(0, -(MIN(0, _xlpm.s_general) + MIN(0, _xlpm.s_reduced))), _xlpm.long_need, MAX(0, -(MIN(0, _xlpm.l_general) + MIN(0, _xlpm.l_reduced) + MIN(0, _xlpm.l_light))), _xlpm.give_lg, IF(AND(_xlpm.short_need>0, _xlpm.long_need=0), MIN(MAX(0, _xlpm.l_general), _xlpm.short_need), 0), _xlpm.rem_s1, IF(AND(_xlpm.short_need>0, _xlpm.long_need=0), _xlpm.short_need - _xlpm.give_lg, 0), _xlpm.give_lr, IF(AND(_xlpm.short_need>0, _xlpm.long_need=0), MIN(MAX(0, _xlpm.l_reduced), _xlpm.rem_s1), 0), _xlpm.take_sg, IF(AND(_xlpm.long_need>0, _xlpm.short_need=0), MIN(MAX(0, _xlpm.s_general), _xlpm.long_need), 0), _xlpm.rem_l1, IF(AND(_xlpm.long_need>0, _xlpm.short_need=0), _xlpm.long_need - _xlpm.take_sg, 0), _xlpm.take_sr, IF(AND(_xlpm.long_need>0, _xlpm.short_need=0), MIN(MAX(0, _xlpm.s_reduced), _xlpm.rem_l1), 0), _xlpm.inc_l_reduced, MIN(MAX(0, -_xlpm.l_reduced), _xlpm.take_sg + _xlpm.take_sr - MIN(MAX(0, -_xlpm.l_general), _xlpm.take_sg + _xlpm.take_sr)), _xlpm.l_reduced - _xlpm.give_lr + _xlpm.inc_l_reduced ) -> 0 | M24: 寄付金控除 | O24: =IF(インプット表!J21+インプット表!J22<2000,0,IF(インプット表!J21<=SUM(O6,O29:O39)*0.4,インプット表!J21,SUM(O6,O29:O39)*0.4)+インプット表!J22-2000) -> 459000 | P24: =IF(W32,0,IF(インプット表!K21+インプット表!K22<2000,0,IF(インプット表!K21<=SUM(P6,P29:P39)*0.4,インプット表!K21,SUM(P6,P29:P39)*0.4)+インプット表!K22-2000)) -> 46000 | Q24: 0 | U24: 市 | V24: =IF(N(インプット表!$J$31)<=2000, 0, (N(インプット表!$J$31)-2000) * $AA$56 * IF($V$6, マスター!$L$20, マスター!$N$20) ) -> 150677.53 | W24: =IF(N(インプット表!$K$31)<=2000, 0, (N(インプット表!$K$31)-2000) * $AB$56 * IF($W$6, マスター!$L$20, マスター!$N$20) ) -> 22022.04 | X24: 0 | Z24: 控除合計 | AA24: =SUM(AA8:AA23) -> 1267927 | AB24: =SUM(AB8:AB23) -> 1470000
B25: 軽課 | C25: =インプット表!C17 -> 0 | E25: =_xlfn.LET( _xlpm.long_general, C23, _xlpm.long_reduced, C24, _xlpm.long_light, C25, _xlpm.need_general, MAX(0, -_xlpm.long_general), _xlpm.move_reduced_to_general, MIN(MAX(0, _xlpm.long_reduced), _xlpm.need_general), _xlpm.lg_a, _xlpm.long_general + _xlpm.move_reduced_to_general, _xlpm.lr_a, _xlpm.long_reduced - _xlpm.move_reduced_to_general, _xlpm.ll_a, _xlpm.long_light, _xlpm.need_general_2, MAX(0, -_xlpm.lg_a), _xlpm.move_light_to_general, MIN(MAX(0, _xlpm.ll_a), _xlpm.need_general_2), _xlpm.lg_b, _xlpm.lg_a + _xlpm.move_light_to_general, _xlpm.lr_b, _xlpm.lr_a, _xlpm.ll_b, _xlpm.ll_a - _xlpm.move_light_to_general, _xlpm.need_reduced, MAX(0, -_xlpm.lr_b), _xlpm.move_general_to_reduced, MIN(MAX(0, _xlpm.lg_b), _xlpm.need_reduced), _xlpm.lg_c, _xlpm.lg_b - _xlpm.move_general_to_reduced, _xlpm.lr_c, _xlpm.lr_b + _xlpm.move_general_to_reduced, _xlpm.need_reduced_2, MAX(0, -_xlpm.lr_c), _xlpm.move_light_to_reduced, MIN(MAX(0, _xlpm.ll_b), _xlpm.need_reduced_2), _xlpm.ll_c, _xlpm.ll_b - _xlpm.move_light_to_reduced, _xlpm.ll_c ) -> 0 | G25: =_xlfn.LET( _xlpm.s_general, E21, _xlpm.s_reduced, E22, _xlpm.l_general, E23, _xlpm.l_reduced, E24, _xlpm.l_light, E25, _xlpm.short_need, MAX(0, -(MIN(0, _xlpm.s_general) + MIN(0, _xlpm.s_reduced))), _xlpm.long_need, MAX(0, -(MIN(0, _xlpm.l_general) + MIN(0, _xlpm.l_reduced) + MIN(0, _xlpm.l_light))), _xlpm.give_lg, IF(AND(_xlpm.short_need>0, _xlpm.long_need=0), MIN(MAX(0, _xlpm.l_general), _xlpm.short_need), 0), _xlpm.rem_s1, IF(AND(_xlpm.short_need>0, _xlpm.long_need=0), _xlpm.short_need - _xlpm.give_lg, 0), _xlpm.give_lr, IF(AND(_xlpm.short_need>0, _xlpm.long_need=0), MIN(MAX(0, _xlpm.l_reduced), _xlpm.rem_s1), 0), _xlpm.rem_s2, IF(AND(_xlpm.short_need>0, _xlpm.long_need=0), _xlpm.rem_s1 - _xlpm.give_lr, 0), _xlpm.give_ll, IF(AND(_xlpm.short_need>0, _xlpm.long_need=0), MIN(MAX(0, _xlpm.l_light), _xlpm.rem_s2), 0), _xlpm.take_sg, IF(AND(_xlpm.long_need>0, _xlpm.short_need=0), MIN(MAX(0, _xlpm.s_general), _xlpm.long_need), 0), _xlpm.rem_l1, IF(AND(_xlpm.long_need>0, _xlpm.short_need=0), _xlpm.long_need - _xlpm.take_sg, 0), _xlpm.take_sr, IF(AND(_xlpm.long_need>0, _xlpm.short_need=0), MIN(MAX(0, _xlpm.s_reduced), _xlpm.rem_l1), 0), _xlpm.inc_l_general, MIN(MAX(0, -_xlpm.l_general), _xlpm.take_sg + _xlpm.take_sr), _xlpm.inc_l_reduced, MIN(MAX(0, -_xlpm.l_reduced), _xlpm.take_sg + _xlpm.take_sr - _xlpm.inc_l_general), _xlpm.inc_l_light, MIN(MAX(0, -_xlpm.l_light), _xlpm.take_sg + _xlpm.take_sr - _xlpm.inc_l_general - _xlpm.inc_l_reduced), _xlpm.l_light - _xlpm.give_ll + _xlpm.inc_l_light ) -> 0 | M25: 控除合計 | O25: =SUM(O21:O24) -> 1876927 | P25: =SUM(P21:P24) -> 1716000 | Q25: =SUM(Q21:Q24) -> 1670000 | U25: 県 | V25: =IF(N(インプット表!$J$31)<=2000, 0, (N(インプット表!$J$31)-2000) * $AA$56 * IF($V$6, マスター!$M$20, マスター!$O$20) ) -> 100451.69 | W25: =IF(N(インプット表!$K$31)<=2000, 0, (N(インプット表!$K$31)-2000) * $AB$56 * IF($W$6, マスター!$M$20, マスター!$O$20) ) -> 14681.36 | X25: 0
U26: 所得割額の20% | V26: 市の20%上限 | Z26: 調整控除
A27: 上場株式等に係る譲渡所得の金額 | C27: =インプット表!C19 -> 0 | E27: =_xlfn.LET( _xlpm.listed_transfer, C27, _xlpm.listed_dividend_pos, MAX(0, C28), _xlpm.use_dividend, MIN(_xlpm.listed_dividend_pos, MAX(0, -_xlpm.listed_transfer)), _xlpm.listed_transfer + _xlpm.use_dividend ) -> 0 | L27: 第三表 | U27: 市 | V27: =N($V$17)*0.2 -> 150456 | W27: =N($W$17)*0.2 -> 42060 | X27: 0 | Z27: ①控除額の計算 | AA27: 前期 | AB27: 当期
A28: 上場株式等に係る配当所得等の金額 | C28: =インプット表!C20 -> 0 | E28: =_xlfn.LET( _xlpm.listed_transfer, C27, _xlpm.listed_dividend_pos, MAX(0, C28), _xlpm.use_dividend, MIN(_xlpm.listed_dividend_pos, MAX(0, -_xlpm.listed_transfer)), MAX(0, C28 - _xlpm.use_dividend) ) -> 0 | U28: 県 | V28: =N($V$18)*0.2 -> 100304 | W28: =N($W$18)*0.2 -> 28040 | X28: 0
L29: 所得金額 | M29: 短期譲渡所得金額 | N29: 一般 | O29: =G21 -> 0 | P29: =G48 -> 0 | Q29: =G48 -> 0 | U29: ↓ | V29: 市の特例(上限適用後)
N30: 軽減 | O30: =G22 -> 0 | P30: =G49 -> 0 | Q30: =G49 -> 0 | U30: 市 | V30: =MIN(N($V$24), N($V$27)) -> 150456 | W30: =ROUNDUP(MIN(N($W$24), N($W$27)),0) -> 22023 | X30: 0 | Z30: ②人的控除額の差 | AA30: 前期 | AB30: 当期
A31: 損益通算（当期） | M31: 長期譲渡所得金額 | N31: 一般 | O31: =G23 -> 0 | P31: =G50 -> 0 | Q31: =G50 -> 0 | U31: 県 | V31: =MIN(N($V$25), N($V$28)) -> 100304 | W31: =ROUNDUP(MIN(N($W$25),N($W$28)),0) -> 14682 | X31: 0 | Z31: 寡婦控除 | AA31: =O12-AA12 -> 0 | AB31: =P12-AB12 -> 0
N32: 特定 | O32: =G24 -> 0 | P32: =G51 -> 0 | Q32: =G51 -> 0 | T32: 申告特例控除 | V32: =AND( インプット表!$J$33, インプット表!$J$34<=5, NOT(インプット表!$J$35) ) -> FALSE | W32: =AND( インプット表!$K$33, インプット表!$K$34<=5, NOT(インプット表!$K$35) ) -> FALSE | X32: =AND( インプット表!$K$33, インプット表!$K$34<=5, NOT(インプット表!$K$35) ) -> FALSE | Z32: ひとり親控除 | AA32: =O13-AA13 -> 0 | AB32: =P13-AB13 -> 0
A33: 譲渡・一時所得の損益の通算 | N33: 軽課 | O33: =G25 -> 0 | P33: =G52 -> 0 | Q33: =G52 -> 0 | U33: 市 | V33: {=ROUNDUP( IF($V$32, MIN(MAX(0,N(インプット表!$J$31)-2000)*$AA$56*INDEX(マスター!$AA$4:$AA$8,MATCH(1,(計算結果!$AA$49>=マスター!$X$4:$X$8)*(計算結果!$AA$49<=IF(マスター!$Z$4:$Z$8="",1E+99,マスター!$Z$4:$Z$8)),0))*IF($V$6,4/5,3/5), N($V$17)*0.2), 0 ),0)} -> 0 | W33: {=ROUNDUP( IF($W$32, MAX(0,N(インプット表!$K$31)-2000)*AB56*INDEX(マスター!$AA$4:$AA$8,MATCH(1,(計算結果!$AB$49>=マスター!$X$4:$X$8)*(計算結果!$AB$49<=IF(マスター!$Z$4:$Z$8="",1E+99,マスター!$Z$4:$Z$8)),0))*IF($W$6,4/5,3/5), 0 ),0)} -> 0 | X33: 0 | Z33: 勤労学生控除 | AA33: =O14-AA14 -> 0 | AB33: =P14-AB14 -> 0
A34: 所得の種類 | C34: 差引金額 | E34: 通算後 | G34: 特別控除 | I34: 譲渡・一時の通算後 | M34: 一般株式等に係る譲渡所得等の金額 | O34: =インプット表!C18 -> 0 | P34: =インプット表!D18 -> 0 | Q34: =インプット表!D18 -> 0 | U34: 県 | V34: {=ROUNDUP( IF($V$32, MIN(MAX(0,N(インプット表!$J$31)-2000)*$AA$56*INDEX(マスター!$AA$4:$AA$8,MATCH(1,(計算結果!$AA$49>=マスター!$X$4:$X$8)*(計算結果!$AA$49<=IF(マスター!$Z$4:$Z$8="",1E+99,マスター!$Z$4:$Z$8)),0))*IF($V$6,1/5,2/5), N($V$18)*0.2), 0 ),0)} -> 0 | W34: {=ROUNDUP( IF($W$32, MIN(MAX(0,N(インプット表!$K$31)-2000)*AB56*INDEX(マスター!$AA$4:$AA$8,MATCH(1,(計算結果!$AB$49>=マスター!$X$4:$X$8)*(計算結果!$AB$49<=IF(マスター!$Z$4:$Z$8="",1E+99,マスター!$Z$4:$Z$8)),0))*IF($W$6,1/5,2/5), N($W$18)*0.2), 0 ),0)} -> 0 | X34: 0 | Z34: 障害者控除 | AA34: =O15-AA15 -> 0 | AB34: =P15-AB15 -> 0
A35: 総合譲渡所得（短期） | C35: =インプット表!D10 -> 0 | E35: =_xlfn.LET( _xlpm.st,C35, _xlpm.lt,C36, _xlpm.pre_st, IF(_xlpm.st*_xlpm.lt<0, IF(ABS(_xlpm.st)>=ABS(_xlpm.lt), _xlpm.st+_xlpm.lt, 0), _xlpm.st), _xlpm.pre_st ) -> 0 | G35: =_xlfn.LET( _xlpm.ps, MAX(0,E35), MIN(500000, _xlpm.ps) ) -> 0 | I35: =_xlfn.LET( _xlpm.short_init, E35 - G35, _xlpm.long_init, E36 - G36, _xlpm.one_init, MAX(0, E37 - G37), _xlpm.need_short, MAX(0, -_xlpm.short_init), _xlpm.use_long_for_short, MIN(MAX(0, _xlpm.long_init), _xlpm.need_short), _xlpm.rem_need_short, _xlpm.need_short - _xlpm.use_long_for_short, _xlpm.use_one_for_short, MIN(_xlpm.one_init, _xlpm.rem_need_short), _xlpm.need_long, MAX(0, -_xlpm.long_init), _xlpm.use_short_for_long, MIN(MAX(0, _xlpm.short_init), _xlpm.need_long), _xlpm.rem_need_long, _xlpm.need_long - _xlpm.use_short_for_long, _xlpm.use_one_for_long, MIN(_xlpm.one_init, _xlpm.rem_need_long), _xlpm.short_after, IF(_xlpm.short_init<0, _xlpm.short_init + _xlpm.use_long_for_short + _xlpm.use_one_for_short, IF(_xlpm.long_init<0, _xlpm.short_init - _xlpm.use_short_for_long, _xlpm.short_init ) ), _xlpm.short_after ) -> 0 | M35: 上場株式等に係る譲渡所得の金額 | O35: =E27 -> 0 | P35: =E54 -> 0 | Q35: =E54 -> 0 | Z35: 配偶者控除 | AA35: =O16-AA16 -> 0 | AB35: =P16-AB16 -> 0
A36: 総合譲渡所得（長期） | C36: =インプット表!D11 -> 0 | E36: =_xlfn.LET( _xlpm.st,C35, _xlpm.lt,C36, _xlpm.pre_lt, IF(_xlpm.st*_xlpm.lt<0, IF(ABS(_xlpm.lt)>ABS(_xlpm.st), _xlpm.st+_xlpm.lt, 0), _xlpm.lt), _xlpm.pre_lt ) -> 0 | G36: =_xlfn.LET( _xlpm.ps, MAX(0,E35), _xlpm.pl, MAX(0,E36), _xlpm.pool, 500000 - MIN(500000, _xlpm.ps), MIN(_xlpm.pool, _xlpm.pl) ) -> 0 | I36: =_xlfn.LET( _xlpm.short_init, E35 - G35, _xlpm.long_init, E36 - G36, _xlpm.one_init, MAX(0, E37 - G37), _xlpm.need_short, MAX(0, -_xlpm.short_init), _xlpm.use_long_for_short, MIN(MAX(0, _xlpm.long_init), _xlpm.need_short), _xlpm.need_long, MAX(0, -_xlpm.long_init), _xlpm.use_short_for_long, MIN(MAX(0, _xlpm.short_init), _xlpm.need_long), _xlpm.rem_need_long, _xlpm.need_long - _xlpm.use_short_for_long, _xlpm.use_one_for_long, MIN(_xlpm.one_init, _xlpm.rem_need_long), _xlpm.long_after, IF(_xlpm.short_init<0, _xlpm.long_init - _xlpm.use_long_for_short, IF(_xlpm.long_init<0, _xlpm.long_init + _xlpm.use_short_for_long + _xlpm.use_one_for_long, _xlpm.long_init ) ), _xlpm.long_after ) -> 0 | M36: 上場株式等に係る配当所得等の金額 | O36: =E28 -> 0 | P36: =E55 -> 0 | Q36: =E55 -> 0 | T36: 結果 | U36: 市 | V36: =ROUNDUP($V$21+IF($V$32,$V$33,$V$30),0) -> 177216 | W36: =ROUNDUP($W$21+$W$33+$W$30,0) -> 24783 | X36: =ROUNDDOWN(X21+X33,-2) -> 0 | Z36: 配偶者特別控除 | AA36: =O17-AA17 -> 0 | AB36: =P17-AB17 -> 0
A37: 一時 | C37: =IF(インプット表!D12<0,0,インプット表!D12) -> 0 | E37: =C37 -> 0 | G37: =_xlfn.LET( _xlpm.pit, MAX(0,E37), MIN(500000, _xlpm.pit) ) -> 0 | I37: =_xlfn.LET( _xlpm.short_init, E35 - G35, _xlpm.long_init, E36 - G36, _xlpm.one_init, MAX(0, E37 - G37), _xlpm.need_short, MAX(0, -_xlpm.short_init), _xlpm.use_long_for_short, MIN(MAX(0, _xlpm.long_init), _xlpm.need_short), _xlpm.rem_need_short, _xlpm.need_short - _xlpm.use_long_for_short, _xlpm.use_one_for_short, MIN(_xlpm.one_init, _xlpm.rem_need_short), _xlpm.need_long, MAX(0, -_xlpm.long_init), _xlpm.use_short_for_long, MIN(MAX(0, _xlpm.short_init), _xlpm.need_long), _xlpm.rem_need_long, _xlpm.need_long - _xlpm.use_short_for_long, _xlpm.use_one_for_long, MIN(_xlpm.one_init, _xlpm.rem_need_long), _xlpm.one_after, IF(_xlpm.short_init<0, _xlpm.one_init - _xlpm.use_one_for_short, IF(_xlpm.long_init<0, _xlpm.one_init - _xlpm.use_one_for_long, _xlpm.one_init ) ), MAX(0, _xlpm.one_after) ) -> 0 | M37: 先物取引に係る雑所得等の金額 | O37: =インプット表!C21 -> 0 | P37: =インプット表!D21 -> 0 | Q37: =インプット表!D21 -> 0 | U37: 県 | V37: =ROUNDUP($V$22+IF($V$32,$V$34,$V$31),0) -> 118144 | W37: =ROUNDUP($W$22+$W$34+$W$31,0) -> 16522 | X37: =ROUNDDOWN(X22+X34,-2) -> 0 | Z37: 扶養控除 | AA37: =O18-AA18 -> 0 | AB37: =P18-AB18 -> 0
M38: 山林所得金額 | O38: =J17 -> 0 | P38: =J44 -> 0 | Q38: =J44 -> 0 | U38: 合計 | V38: =SUM(V36:V37) -> 295360 | W38: =SUM(W36:W37) -> 41305 | X38: =SUM(X36:X37) -> 0 | Z38: 基礎控除 | AA38: =IF(AA6>25000000,0,50000) -> 50000 | AB38: =IF(AB6>25000000,0,50000) -> 50000
C39: 通算前 | E39: 第1次通算後 | G39: 第2次通算後 | I39: 第3次通算後 | J39: 所得金額 | M39: 退職所得金額 | O39: =J18 -> 0 | P39: =J45 -> 0 | Q39: =J45 -> 0 | Z39: 人的控除額の差の合計額 | AA39: =IF(AA6>25000000,0,SUM(AA31:AA38)) -> 50000 | AB39: =IF(AB6>25000000,0,SUM(AB31:AB38)) -> 50000
A40: 経常所得 | C40: =SUM(インプット表!D2,インプット表!D3,インプット表!D4,IF(インプット表!D5<0,0,インプット表!D5),IF(インプット表!D6<0,0,インプット表!D6),IF(インプット表!D7<0,0,インプット表!D7),IF(インプット表!D8<0,0,インプット表!D8),IF(インプット表!D9<0,0,インプット表!D9)) -> 5000000 | D40: 第1次 | E40: =_xlfn.LET( _xlpm.econ,C40, _xlpm.shortT,C41, _xlpm.longT,C42, _xlpm.oneTime,C43, _xlpm.econ_pos,MAX(0,_xlpm.econ), _xlpm.lt_neg,MAX(0,-_xlpm.longT), _xlpm.st_neg,MAX(0,-_xlpm.shortT), _xlpm.use_econ,MIN(_xlpm.econ_pos, _xlpm.lt_neg+_xlpm.st_neg), _xlpm.lt_raise,MIN(_xlpm.use_econ, _xlpm.lt_neg), _xlpm.st_raise,MIN(_xlpm.use_econ-_xlpm.lt_raise, _xlpm.st_neg), _xlpm.econ_after, _xlpm.econ-(_xlpm.lt_raise+_xlpm.st_raise), _xlpm.st_after, _xlpm.shortT+_xlpm.st_raise, _xlpm.lt_after, _xlpm.longT+_xlpm.lt_raise, _xlpm.it_after, _xlpm.oneTime, _xlpm.econ_neg,MAX(0,-_xlpm.econ_after), _xlpm.use_from_st,MIN(MAX(0,_xlpm.st_after), _xlpm.econ_neg), _xlpm.use_from_lt,MIN(MAX(0,_xlpm.lt_after), _xlpm.econ_neg-_xlpm.use_from_st), _xlpm.use_from_it,MIN(MAX(0,_xlpm.it_after), _xlpm.econ_neg-_xlpm.use_from_st-_xlpm.use_from_lt), _xlpm.econ_after + _xlpm.use_from_st + _xlpm.use_from_lt + _xlpm.use_from_it ) -> 5000000 | F40: 第2次 | G40: =_xlfn.LET( _xlpm.econ,E40, _xlpm.st,E41, _xlpm.lt,E42, _xlpm.it,E43, _xlpm.forest,E44, _xlpm.forest_pos,MAX(0,_xlpm.forest), _xlpm.forest_neg,MAX(0,-_xlpm.forest), _xlpm.ltNeg,MAX(0,-_xlpm.lt), _xlpm.stNeg,MAX(0,-_xlpm.st), _xlpm.econNeg,MAX(0,-_xlpm.econ), _xlpm.ltPos,MAX(0,_xlpm.lt), _xlpm.stPos,MAX(0,_xlpm.st), _xlpm.econPos,MAX(0,_xlpm.econ), _xlpm.itPos,MAX(0,_xlpm.it), _xlpm.use_lt_pos, MIN(_xlpm.forest_pos, _xlpm.ltNeg), _xlpm.use_st_pos, MIN(_xlpm.forest_pos-_xlpm.use_lt_pos, _xlpm.stNeg), _xlpm.use_econ_pos,MIN(_xlpm.forest_pos-_xlpm.use_lt_pos-_xlpm.use_st_pos, _xlpm.econNeg), _xlpm.econ_when_pos, _xlpm.econ + _xlpm.use_econ_pos, _xlpm.use_from_econ, MIN(_xlpm.econPos, _xlpm.forest_neg), _xlpm.use_from_st, MIN(_xlpm.stPos, _xlpm.forest_neg - _xlpm.use_from_econ), _xlpm.use_from_lt, MIN(_xlpm.ltPos, _xlpm.forest_neg - _xlpm.use_from_econ - _xlpm.use_from_st), _xlpm.use_from_it, MIN(_xlpm.itPos, _xlpm.forest_neg - _xlpm.use_from_econ - _xlpm.use_from_st - _xlpm.use_from_lt), _xlpm.econ_when_neg, _xlpm.econ - _xlpm.use_from_econ, IF(_xlpm.forest>=0, _xlpm.econ_when_pos, _xlpm.econ_when_neg) ) -> 5000000 | H40: 第3次 | I40: =_xlfn.LET( _xlpm.econ,G40, _xlpm.st,G41, _xlpm.lt,G42, _xlpm.it,G43, _xlpm.forest,G44, _xlpm.retire,G45, _xlpm.ret_pos,MAX(0,_xlpm.retire), _xlpm.neg_lt,MAX(0,-_xlpm.lt), _xlpm.neg_st,MAX(0,-_xlpm.st), _xlpm.neg_econ,MAX(0,-_xlpm.econ), _xlpm.neg_for,MAX(0,-_xlpm.forest), _xlpm.use_lt,MIN(_xlpm.ret_pos,_xlpm.neg_lt), _xlpm.use_st,MIN(_xlpm.ret_pos-_xlpm.use_lt,_xlpm.neg_st), _xlpm.use_econ,MIN(_xlpm.ret_pos-_xlpm.use_lt-_xlpm.use_st,_xlpm.neg_econ), _xlpm.use_for,MIN(_xlpm.ret_pos-_xlpm.use_lt-_xlpm.use_st-_xlpm.use_econ,_xlpm.neg_for), _xlpm.econ + _xlpm.use_econ ) -> 5000000 | J40: =I40 -> 5000000 | L40: 課税される所得金額 | M40: 総合課税の合計額 | O40: =O6 -> 13831070 | P40: =P6 -> 5000000 | Q40: =Q6 -> 5000000
A41: 総合譲渡所得（短期） | C41: =I35 -> 0 | E41: =_xlfn.LET( _xlpm.econ,C40, _xlpm.shortT,C41, _xlpm.longT,C42, _xlpm.oneTime,C43, _xlpm.econ_pos,MAX(0,_xlpm.econ), _xlpm.lt_neg,MAX(0,-_xlpm.longT), _xlpm.st_neg,MAX(0,-_xlpm.shortT), _xlpm.use_econ,MIN(_xlpm.econ_pos, _xlpm.lt_neg+_xlpm.st_neg), _xlpm.lt_raise,MIN(_xlpm.use_econ, _xlpm.lt_neg), _xlpm.st_raise,MIN(_xlpm.use_econ-_xlpm.lt_raise, _xlpm.st_neg), _xlpm.econ_after, _xlpm.econ-(_xlpm.lt_raise+_xlpm.st_raise), _xlpm.st_after, _xlpm.shortT+_xlpm.st_raise, _xlpm.econ_neg,MAX(0,-_xlpm.econ_after), _xlpm.use_from_st,MIN(MAX(0,_xlpm.st_after), _xlpm.econ_neg), _xlpm.st_after - _xlpm.use_from_st ) -> 0 | G41: =_xlfn.LET( _xlpm.econ,E40, _xlpm.st,E41, _xlpm.lt,E42, _xlpm.it,E43, _xlpm.forest,E44, _xlpm.forest_pos,MAX(0,_xlpm.forest), _xlpm.forest_neg,MAX(0,-_xlpm.forest), _xlpm.ltNeg,MAX(0,-_xlpm.lt), _xlpm.stNeg,MAX(0,-_xlpm.st), _xlpm.ltPos,MAX(0,_xlpm.lt), _xlpm.stPos,MAX(0,_xlpm.st), _xlpm.itPos,MAX(0,_xlpm.it), _xlpm.econPos,MAX(0,_xlpm.econ), _xlpm.use_lt_pos, MIN(_xlpm.forest_pos, _xlpm.ltNeg), _xlpm.use_st_pos, MIN(_xlpm.forest_pos-_xlpm.use_lt_pos, _xlpm.stNeg), _xlpm.st_when_pos, _xlpm.st + _xlpm.use_st_pos, _xlpm.use_from_econ, MIN(_xlpm.econPos, _xlpm.forest_neg), _xlpm.use_from_st, MIN(_xlpm.stPos, _xlpm.forest_neg - _xlpm.use_from_econ), _xlpm.st_when_neg, _xlpm.st - _xlpm.use_from_st, IF(_xlpm.forest>=0, _xlpm.st_when_pos, _xlpm.st_when_neg) ) -> 0 | I41: =_xlfn.LET( _xlpm.econ,G40, _xlpm.st,G41, _xlpm.lt,G42, _xlpm.it,G43, _xlpm.forest,G44, _xlpm.retire,G45, _xlpm.ret_pos,MAX(0,_xlpm.retire), _xlpm.neg_lt,MAX(0,-_xlpm.lt), _xlpm.neg_st,MAX(0,-_xlpm.st), _xlpm.neg_econ,MAX(0,-_xlpm.econ), _xlpm.neg_for,MAX(0,-_xlpm.forest), _xlpm.use_lt,MIN(_xlpm.ret_pos,_xlpm.neg_lt), _xlpm.use_st,MIN(_xlpm.ret_pos-_xlpm.use_lt,_xlpm.neg_st), _xlpm.st + _xlpm.use_st ) -> 0 | J41: =I41 -> 0 | M41: 所得から差し引かれる金額 | O41: =MIN(O25, O40) -> 1876927 | P41: =MIN(P25, P40) -> 1716000 | Q41: =Q25 -> 1670000 | Z41: 特例控除の控除率の決定 | AA41: 前期 | AB41: 当期
A42: 総合譲渡所得（長期） | C42: =I36 -> 0 | E42: =_xlfn.LET( _xlpm.econ,C40, _xlpm.shortT,C41, _xlpm.longT,C42, _xlpm.oneTime,C43, _xlpm.econ_pos,MAX(0,_xlpm.econ), _xlpm.lt_neg,MAX(0,-_xlpm.longT), _xlpm.st_neg,MAX(0,-_xlpm.shortT), _xlpm.use_econ,MIN(_xlpm.econ_pos, _xlpm.lt_neg+_xlpm.st_neg), _xlpm.lt_raise,MIN(_xlpm.use_econ, _xlpm.lt_neg), _xlpm.st_raise,MIN(_xlpm.use_econ-_xlpm.lt_raise, _xlpm.st_neg), _xlpm.econ_after, _xlpm.econ-(_xlpm.lt_raise+_xlpm.st_raise), _xlpm.lt_after, _xlpm.longT+_xlpm.lt_raise, _xlpm.econ_neg,MAX(0,-_xlpm.econ_after), _xlpm.use_from_st,MIN(MAX(0,_xlpm.shortT+_xlpm.st_raise), _xlpm.econ_neg), _xlpm.use_from_lt,MIN(MAX(0,_xlpm.lt_after), _xlpm.econ_neg-_xlpm.use_from_st), _xlpm.lt_after - _xlpm.use_from_lt ) -> 0 | G42: =_xlfn.LET( _xlpm.econ,E40, _xlpm.st,E41, _xlpm.lt,E42, _xlpm.it,E43, _xlpm.forest,E44, _xlpm.forest_pos,MAX(0,_xlpm.forest), _xlpm.forest_neg,MAX(0,-_xlpm.forest), _xlpm.ltNeg,MAX(0,-_xlpm.lt), _xlpm.stNeg,MAX(0,-_xlpm.st), _xlpm.ltPos,MAX(0,_xlpm.lt), _xlpm.stPos,MAX(0,_xlpm.st), _xlpm.itPos,MAX(0,_xlpm.it), _xlpm.econPos,MAX(0,_xlpm.econ), _xlpm.use_lt_pos, MIN(_xlpm.forest_pos, _xlpm.ltNeg), _xlpm.lt_when_pos, _xlpm.lt + _xlpm.use_lt_pos, _xlpm.use_from_econ, MIN(_xlpm.econPos, _xlpm.forest_neg), _xlpm.use_from_st, MIN(_xlpm.stPos, _xlpm.forest_neg - _xlpm.use_from_econ), _xlpm.use_from_lt, MIN(_xlpm.ltPos, _xlpm.forest_neg - _xlpm.use_from_econ - _xlpm.use_from_st), _xlpm.lt_when_neg, _xlpm.lt - _xlpm.use_from_lt, IF(_xlpm.forest>=0, _xlpm.lt_when_pos, _xlpm.lt_when_neg) ) -> 0 | I42: =_xlfn.LET( _xlpm.econ,G40, _xlpm.st,G41, _xlpm.lt,G42, _xlpm.it,G43, _xlpm.forest,G44, _xlpm.retire,G45, _xlpm.ret_pos,MAX(0,_xlpm.retire), _xlpm.neg_lt,MAX(0,-_xlpm.lt), _xlpm.neg_st,MAX(0,-_xlpm.st), _xlpm.neg_econ,MAX(0,-_xlpm.econ), _xlpm.neg_for,MAX(0,-_xlpm.forest), _xlpm.use_lt,MIN(_xlpm.ret_pos,_xlpm.neg_lt), _xlpm.lt + _xlpm.use_lt ) -> 0 | J42: =I42/2 -> 0 | M42: 総合課税 | O42: =ROUNDDOWN(O40 - O41,-3) -> 11954000 | P42: =ROUNDDOWN(P40 - P41,-3) -> 3284000 | Q42: =ROUNDDOWN(Q40 - Q41,-3) -> 3330000 | Z42: 課税所得(総合) | AA42: =INDEX($O:$O, MATCH("総合課税",$M:$M,0)) -> 11954000 | AB42: =INDEX($P:$P, MATCH("総合課税",$M:$M,0)) -> 3284000
...

Sheet 簡便版
D2: ワンストップ特例なし | M2: ワンストップ特例あり
E4: 寄付前① | F4: 寄付後② | G4: 差額(①－②) | N4: 寄付前① | O4: 寄付後② | P4: 差額(①－②)
B5: 所得税 | C5: 寄付した額 | E5: 0 | F5: =インプット表!K22 -> 48000 | G5: =+E5-F5 -> -48000 | K5: 所得税 | L5: 寄付した額 | N5: 0 | O5: =インプット表!K22 -> 48000 | P5: =+N5-O5 -> -48000
C6: 総合課税の合計額 | E6: =計算結果!Q6 -> 5000000 | F6: =+E6 -> 5000000 | G6: =+E6-F6 -> 0 | L6: 総合課税の合計額 | N6: =計算結果!Q6 -> 5000000 | O6: =+N6 -> 5000000 | P6: =+N6-O6 -> 0
C7: 所得控除額 | E7: =計算結果!Q25 -> 1670000 | F7: =+E7+F5-2000 -> 1716000 | G7: =+E7-F7 -> -46000 | L7: 所得控除額 | N7: =計算結果!Q25 -> 1670000 | O7: =計算結果!Q25 -> 1670000 | P7: =+N7-O7 -> 0
C8: 分離課税所得 | D8: 短期譲渡 | E8: =計算結果!Q29 -> 0 | F8: =+E8 -> 0 | G8: =+E8-F8 -> 0 | L8: 分離課税所得 | M8: 短期譲渡 | N8: =計算結果!Q29 -> 0 | O8: =+N8 -> 0 | P8: =+N8-O8 -> 0
D9: 長期譲渡 | E9: =計算結果!Q31 -> 0 | F9: =+E9 -> 0 | G9: =+E9-F9 -> 0 | M9: 長期譲渡 | N9: =計算結果!Q31 -> 0 | O9: =+N9 -> 0 | P9: =+N9-O9 -> 0
C10: 税 額 | D10: 総合課税(累進税率) | E10: =計算結果!Q50*1.021 -> 243508.5 | F10: =計算結果!P50*1.021 -> 235748.9 | G10: =E10-F10 -> 7759.6 | L10: 税 額 | M10: 総合課税(累進税率) | N10: =計算結果!Q50*1.021 -> 243508.5 | O10: =計算結果!P50*1.021 -> 235748.9
